<?xml version="1.0" encoding="utf-8"?>
<robot name="partnet_811c349efc40c6feaf288f952624966">
 <link name="base"/>
 <link name="link_0">
  <visual name="lever-43">
   <origin xyz="0.08663812725804754 0.1477292507709976 0"/>
   <geometry>
    <mesh filename="textured_objs/original-21.obj"/>
   </geometry>
  </visual>
  <collision>
   <geometry>
    <mesh filename="cvx_objs/link_0.obj"/>
   </geometry>
  </collision>
 </link>
 <joint name="joint_0" type="revolute">
  <origin xyz="-0.09161512725804753 -0.1477292507709976 -0.056823"/>
  <axis xyz="0 0 1"/>
  <child link="link_0"/>
  <parent link="link_12"/>
  <limit lower="0.0" upper="0.20106192982974674"/>
 </joint>
 <link name="link_1">
  <visual name="lever-44">
   <origin xyz="-0.08782858145423231 0.1379207742877884 0"/>
   <geometry>
    <mesh filename="textured_objs/original-20.obj"/>
   </geometry>
  </visual>
  <collision>
   <geometry>
    <mesh filename="cvx_objs/link_1.obj"/>
   </geometry>
  </collision>
 </link>
 <joint name="joint_1" type="revolute">
  <origin xyz="0.08285158145423231 -0.1379207742877884 -0.056823"/>
  <axis xyz="0 0 -1"/>
  <child link="link_1"/>
  <parent link="link_12"/>
  <limit lower="-0.0" upper="0.20106192982974674"/>
 </joint>
 <link name="link_2">
  <visual name="wheel-41">
   <origin xyz="0.5249780501654557 0.7313998264037611 0.15098083059845893"/>
   <geometry>
    <mesh filename="textured_objs/original-38.obj"/>
   </geometry>
  </visual>
  <collision>
   <geometry>
    <mesh filename="cvx_objs/link_2.obj"/>
   </geometry>
  </collision>
 </link>
 <joint name="joint_2" type="continuous">
  <origin xyz="0.03424050135652712 -0.7313998264037611 -0.04638946615722139"/>
  <axis xyz="-0.2760123304846159 -0.0002945439074830451 0.9611540493928836"/>
  <child link="link_2"/>
  <parent link="link_14"/>
 </joint>
 <link name="link_3">
  <visual name="wheel-42">
   <origin xyz="0.5249780501654557 0.7313998264037611 0.15098083059845893"/>
   <geometry>
    <mesh filename="textured_objs/original-39.obj"/>
   </geometry>
  </visual>
  <collision>
   <geometry>
    <mesh filename="cvx_objs/link_3.obj"/>
   </geometry>
  </collision>
 </link>
 <joint name="joint_3" type="continuous">
  <origin xyz="0.03424050135652712 -0.7313998264037611 -0.04638946615722139"/>
  <axis xyz="-0.2760123304846159 -0.0002945439074830451 0.9611540493928836"/>
  <child link="link_3"/>
  <parent link="link_14"/>
 </joint>
 <link name="link_4">
  <visual name="wheel-37">
   <origin xyz="0.017212425981784695 0.7313732533845521 0.5092680747368981"/>
   <geometry>
    <mesh filename="textured_objs/original-34.obj"/>
   </geometry>
  </visual>
  <collision>
   <geometry>
    <mesh filename="cvx_objs/link_4.obj"/>
   </geometry>
  </collision>
 </link>
 <joint name="joint_4" type="continuous">
  <origin xyz="-0.0006666514038856861 -0.7313732533845521 0.020076167880698215"/>
  <axis xyz="-0.9993214504172013 -0.0020875243364418252 0.036773373223108224"/>
  <child link="link_4"/>
  <parent link="link_15"/>
 </joint>
 <link name="link_5">
  <visual name="wheel-38">
   <origin xyz="0.017212425981784695 0.7313732533845521 0.5092680747368981"/>
   <geometry>
    <mesh filename="textured_objs/original-35.obj"/>
   </geometry>
  </visual>
  <collision>
   <geometry>
    <mesh filename="cvx_objs/link_5.obj"/>
   </geometry>
  </collision>
 </link>
 <joint name="joint_5" type="continuous">
  <origin xyz="-0.0006666514038856861 -0.7313732533845521 0.020076167880698215"/>
  <axis xyz="-0.9993214504172013 -0.0020875243364418252 0.036773373223108224"/>
  <child link="link_5"/>
  <parent link="link_15"/>
 </joint>
 <link name="link_6">
  <visual name="wheel-33">
   <origin xyz="-0.5176517469256298 0.7314251792291601 0.18870106421570007"/>
   <geometry>
    <mesh filename="textured_objs/original-30.obj"/>
   </geometry>
  </visual>
  <collision>
   <geometry>
    <mesh filename="cvx_objs/link_6.obj"/>
   </geometry>
  </collision>
 </link>
 <joint name="joint_6" type="continuous">
  <origin xyz="-0.037509291601474315 -0.7314251792291601 -0.04422003904003455"/>
  <axis xyz="0.342426876959796 -4.809964583497058e-05 0.9395444809172074"/>
  <child link="link_6"/>
  <parent link="link_16"/>
 </joint>
 <link name="link_7">
  <visual name="wheel-34">
   <origin xyz="-0.5176517469256298 0.7314251792291601 0.18870106421570007"/>
   <geometry>
    <mesh filename="textured_objs/original-31.obj"/>
   </geometry>
  </visual>
  <collision>
   <geometry>
    <mesh filename="cvx_objs/link_7.obj"/>
   </geometry>
  </collision>
 </link>
 <joint name="joint_7" type="continuous">
  <origin xyz="-0.037509291601474315 -0.7314251792291601 -0.04422003904003455"/>
  <axis xyz="0.342426876959796 -4.809964583497058e-05 0.9395444809172074"/>
  <child link="link_7"/>
  <parent link="link_16"/>
 </joint>
 <link name="link_8">
  <visual name="wheel-29">
   <origin xyz="-0.3778363370334372 0.7314265 -0.483205965717323"/>
   <geometry>
    <mesh filename="textured_objs/original-46.obj"/>
   </geometry>
  </visual>
  <collision>
   <geometry>
    <mesh filename="cvx_objs/link_8.obj"/>
   </geometry>
  </collision>
 </link>
 <joint name="joint_8" type="continuous">
  <origin xyz="0.012085030010775044 -0.7314265 -0.03495326308582347"/>
  <axis xyz="0.7877619511607603 0 -0.6159797953694522"/>
  <child link="link_8"/>
  <parent link="link_17"/>
 </joint>
 <link name="link_9">
  <visual name="wheel-30">
   <origin xyz="-0.3778363370334372 0.7314265 -0.483205965717323"/>
   <geometry>
    <mesh filename="textured_objs/original-47.obj"/>
   </geometry>
  </visual>
  <collision>
   <geometry>
    <mesh filename="cvx_objs/link_9.obj"/>
   </geometry>
  </collision>
 </link>
 <joint name="joint_9" type="continuous">
  <origin xyz="0.012085030010775044 -0.7314265 -0.03495326308582347"/>
  <axis xyz="0.7877619511607603 0 -0.6159797953694522"/>
  <child link="link_9"/>
  <parent link="link_17"/>
 </joint>
 <link name="link_10">
  <visual name="wheel-25">
   <origin xyz="0.34037500044103797 0.7314721903000174 -0.5069054484051658"/>
   <geometry>
    <mesh filename="textured_objs/original-42.obj"/>
   </geometry>
  </visual>
  <collision>
   <geometry>
    <mesh filename="cvx_objs/link_10.obj"/>
   </geometry>
  </collision>
 </link>
 <joint name="joint_10" type="continuous">
  <origin xyz="-0.017397499313034304 -0.7314721903000174 -0.03590658568194949"/>
  <axis xyz="0.8297053052480169 0.0007440671274425703 0.5582011759280028"/>
  <child link="link_10"/>
  <parent link="link_18"/>
 </joint>
 <link name="link_11">
  <visual name="wheel-26">
   <origin xyz="0.34037500044103797 0.7314721903000174 -0.5069054484051658"/>
   <geometry>
    <mesh filename="textured_objs/original-43.obj"/>
   </geometry>
  </visual>
  <collision>
   <geometry>
    <mesh filename="cvx_objs/link_11.obj"/>
   </geometry>
  </collision>
 </link>
 <joint name="joint_11" type="continuous">
  <origin xyz="-0.017397499313034304 -0.7314721903000174 -0.03590658568194949"/>
  <axis xyz="0.8297053052480169 0.0007440671274425703 0.5582011759280028"/>
  <child link="link_11"/>
  <parent link="link_18"/>
 </joint>
 <link name="link_12">
  <visual name="back_support-58">
   <origin xyz="-0.0049770000000000005 0 -0.056823"/>
   <geometry>
    <mesh filename="textured_objs/original-53.obj"/>
   </geometry>
  </visual>
  <visual name="back_connector-60">
   <origin xyz="-0.0049770000000000005 0 -0.056823"/>
   <geometry>
    <mesh filename="textured_objs/original-54.obj"/>
   </geometry>
  </visual>
  <visual name="back_connector-60">
   <origin xyz="-0.0049770000000000005 0 -0.056823"/>
   <geometry>
    <mesh filename="textured_objs/original-27.obj"/>
   </geometry>
  </visual>
  <visual name="back_soft_surface-62">
   <origin xyz="-0.0049770000000000005 0 -0.056823"/>
   <geometry>
    <mesh filename="textured_objs/original-50.obj"/>
   </geometry>
  </visual>
  <visual name="armrest_hard_surface-55">
   <origin xyz="-0.0049770000000000005 0 -0.056823"/>
   <geometry>
    <mesh filename="textured_objs/original-9.obj"/>
   </geometry>
  </visual>
  <visual name="armrest_hard_surface-55">
   <origin xyz="-0.0049770000000000005 0 -0.056823"/>
   <geometry>
    <mesh filename="textured_objs/original-8.obj"/>
   </geometry>
  </visual>
  <visual name="arm_vertical_bar-56">
   <origin xyz="-0.0049770000000000005 0 -0.056823"/>
   <geometry>
    <mesh filename="textured_objs/original-7.obj"/>
   </geometry>
  </visual>
  <visual name="arm_horizontal_bar-57">
   <origin xyz="-0.0049770000000000005 0 -0.056823"/>
   <geometry>
    <mesh filename="textured_objs/original-10.obj"/>
   </geometry>
  </visual>
  <visual name="armrest_hard_surface-52">
   <origin xyz="-0.0049770000000000005 0 -0.056823"/>
   <geometry>
    <mesh filename="textured_objs/original-4.obj"/>
   </geometry>
  </visual>
  <visual name="armrest_hard_surface-52">
   <origin xyz="-0.0049770000000000005 0 -0.056823"/>
   <geometry>
    <mesh filename="textured_objs/original-5.obj"/>
   </geometry>
  </visual>
  <visual name="arm_vertical_bar-53">
   <origin xyz="-0.0049770000000000005 0 -0.056823"/>
   <geometry>
    <mesh filename="textured_objs/original-3.obj"/>
   </geometry>
  </visual>
  <visual name="arm_horizontal_bar-54">
   <origin xyz="-0.0049770000000000005 0 -0.056823"/>
   <geometry>
    <mesh filename="textured_objs/original-6.obj"/>
   </geometry>
  </visual>
  <visual name="seat_soft_surface-50">
   <origin xyz="-0.0049770000000000005 0 -0.056823"/>
   <geometry>
    <mesh filename="textured_objs/original-49.obj"/>
   </geometry>
  </visual>
  <visual name="seat_support-51">
   <origin xyz="-0.0049770000000000005 0 -0.056823"/>
   <geometry>
    <mesh filename="textured_objs/original-52.obj"/>
   </geometry>
  </visual>
  <visual name="central_support-47">
   <origin xyz="-0.0049770000000000005 0 -0.056823"/>
   <geometry>
    <mesh filename="textured_objs/original-19.obj"/>
   </geometry>
  </visual>
  <visual name="mounting_plate-45">
   <origin xyz="-0.0049770000000000005 0 -0.056823"/>
   <geometry>
    <mesh filename="textured_objs/original-23.obj"/>
   </geometry>
  </visual>
  <visual name="mounting_plate-45">
   <origin xyz="-0.0049770000000000005 0 -0.056823"/>
   <geometry>
    <mesh filename="textured_objs/original-25.obj"/>
   </geometry>
  </visual>
  <visual name="mounting_plate-45">
   <origin xyz="-0.0049770000000000005 0 -0.056823"/>
   <geometry>
    <mesh filename="textured_objs/original-24.obj"/>
   </geometry>
  </visual>
  <visual name="mounting_plate-63">
   <origin xyz="-0.0049770000000000005 0 -0.056823"/>
   <geometry>
    <mesh filename="textured_objs/original-26.obj"/>
   </geometry>
  </visual>
  <collision>
   <geometry>
    <mesh filename="cvx_objs/link_12.obj"/>
   </geometry>
  </collision>
 </link>
 <joint name="joint_12" type="continuous">
  <origin xyz="0.0 0 0.0"/>
  <axis xyz="0 1 0"/>
  <child link="link_12"/>
  <parent link="link_12_helper"/>
 </joint>
 <link name="link_13">
  <visual name="central_support-46">
   <origin xyz="0 0 0"/>
   <geometry>
    <mesh filename="textured_objs/original-12.obj"/>
   </geometry>
  </visual>
  <visual name="central_support-48">
   <origin xyz="0 0 0"/>
   <geometry>
    <mesh filename="textured_objs/original-18.obj"/>
   </geometry>
  </visual>
  <visual name="leg-10">
   <origin xyz="0 0 0"/>
   <geometry>
    <mesh filename="textured_objs/original-15.obj"/>
   </geometry>
  </visual>
  <visual name="leg-11">
   <origin xyz="0 0 0"/>
   <geometry>
    <mesh filename="textured_objs/original-16.obj"/>
   </geometry>
  </visual>
  <visual name="leg-12">
   <origin xyz="0 0 0"/>
   <geometry>
    <mesh filename="textured_objs/original-17.obj"/>
   </geometry>
  </visual>
  <visual name="leg-13">
   <origin xyz="0 0 0"/>
   <geometry>
    <mesh filename="textured_objs/original-13.obj"/>
   </geometry>
  </visual>
  <visual name="leg-14">
   <origin xyz="0 0 0"/>
   <geometry>
    <mesh filename="textured_objs/original-14.obj"/>
   </geometry>
  </visual>
  <collision>
   <geometry>
    <mesh filename="cvx_objs/link_13.obj"/>
   </geometry>
  </collision>
 </link>
 <joint name="joint_13" type="fixed">
  <origin rpy="1.570796326794897 0 -1.570796326794897" xyz="0 0 0"/>
  <child link="link_13"/>
  <parent link="base"/>
 </joint>
 <link name="link_14">
  <visual name="caster_yoke-39">
   <origin xyz="0.5592185515219829 0 0.10459136444123754"/>
   <geometry>
    <mesh filename="textured_objs/original-37.obj"/>
   </geometry>
  </visual>
  <visual name="caster_stem-40">
   <origin xyz="0.5592185515219829 0 0.10459136444123754"/>
   <geometry>
    <mesh filename="textured_objs/original-36.obj"/>
   </geometry>
  </visual>
  <collision>
   <geometry>
    <mesh filename="cvx_objs/link_14.obj"/>
   </geometry>
  </collision>
 </link>
 <joint name="joint_14" type="continuous">
  <origin xyz="-0.5592185515219829 0 -0.10459136444123754"/>
  <axis xyz="0 1 0"/>
  <child link="link_14"/>
  <parent link="link_13"/>
 </joint>
 <link name="link_15">
  <visual name="caster_yoke-35">
   <origin xyz="0.01654577457789901 0 0.5293442426175963"/>
   <geometry>
    <mesh filename="textured_objs/original-33.obj"/>
   </geometry>
  </visual>
  <visual name="caster_stem-36">
   <origin xyz="0.01654577457789901 0 0.5293442426175963"/>
   <geometry>
    <mesh filename="textured_objs/original-32.obj"/>
   </geometry>
  </visual>
  <collision>
   <geometry>
    <mesh filename="cvx_objs/link_15.obj"/>
   </geometry>
  </collision>
 </link>
 <joint name="joint_15" type="continuous">
  <origin xyz="-0.01654577457789901 0 -0.5293442426175963"/>
  <axis xyz="0 1 0"/>
  <child link="link_15"/>
  <parent link="link_13"/>
 </joint>
 <link name="link_16">
  <visual name="caster_yoke-31">
   <origin xyz="-0.5551610385271041 0 0.14448102517566552"/>
   <geometry>
    <mesh filename="textured_objs/original-29.obj"/>
   </geometry>
  </visual>
  <visual name="caster_stem-32">
   <origin xyz="-0.5551610385271041 0 0.14448102517566552"/>
   <geometry>
    <mesh filename="textured_objs/original-28.obj"/>
   </geometry>
  </visual>
  <collision>
   <geometry>
    <mesh filename="cvx_objs/link_16.obj"/>
   </geometry>
  </collision>
 </link>
 <joint name="joint_16" type="continuous">
  <origin xyz="0.5551610385271041 0 -0.14448102517566552"/>
  <axis xyz="0 1 0"/>
  <child link="link_16"/>
  <parent link="link_13"/>
 </joint>
 <link name="link_17">
  <visual name="caster_yoke-27">
   <origin xyz="-0.3657513070226622 0 -0.5181592288031465"/>
   <geometry>
    <mesh filename="textured_objs/original-45.obj"/>
   </geometry>
  </visual>
  <visual name="caster_stem-28">
   <origin xyz="-0.3657513070226622 0 -0.5181592288031465"/>
   <geometry>
    <mesh filename="textured_objs/original-44.obj"/>
   </geometry>
  </visual>
  <collision>
   <geometry>
    <mesh filename="cvx_objs/link_17.obj"/>
   </geometry>
  </collision>
 </link>
 <joint name="joint_17" type="continuous">
  <origin xyz="0.3657513070226622 0 0.5181592288031465"/>
  <axis xyz="0 1 0"/>
  <child link="link_17"/>
  <parent link="link_13"/>
 </joint>
 <link name="link_18">
  <visual name="caster_yoke-23">
   <origin xyz="0.32297750112800366 0 -0.5428120340871153"/>
   <geometry>
    <mesh filename="textured_objs/original-41.obj"/>
   </geometry>
  </visual>
  <visual name="caster_stem-24">
   <origin xyz="0.32297750112800366 0 -0.5428120340871153"/>
   <geometry>
    <mesh filename="textured_objs/original-40.obj"/>
   </geometry>
  </visual>
  <collision>
   <geometry>
    <mesh filename="cvx_objs/link_18.obj"/>
   </geometry>
  </collision>
 </link>
 <joint name="joint_18" type="continuous">
  <origin xyz="-0.32297750112800366 0 0.5428120340871153"/>
  <axis xyz="0 1 0"/>
  <child link="link_18"/>
  <parent link="link_13"/>
 </joint>
 <link name="link_12_helper"/>
 <joint name="joint_19" type="prismatic">
  <origin xyz="0.0049770000000000005 0 0.056823"/>
  <axis xyz="0 -1 0"/>
  <child link="link_12_helper"/>
  <parent link="link_13"/>
  <limit lower="0" upper="0.06800000000000006"/>
 </joint>
</robot>