<?xml version="1.0" ?>
<robot name="partnet_a33fcf84726cd862d866e3aa112e4663">
	<link name="base"/>
	<link name="link_0">
		<visual name="caster_stem-34">
			<origin xyz="0.26527999999999996 0 0.220503"/>
			<geometry>
				<mesh filename="textured_objs/original-11.obj"/>
			</geometry>
		</visual>
		<collision>
			<origin xyz="0.26527999999999996 0 0.220503"/>
			<geometry>
				<mesh filename="textured_objs/original-11.obj"/>
			</geometry>
		</collision>
	</link>
	<joint name="joint_0" type="continuous">
		<origin xyz="-0.26527999999999996 0 -0.220503"/>
		<axis xyz="0 1 0"/>
		<child link="link_0"/>
		<parent link="link_11"/>
	</joint>
	<link name="link_1">
		<visual name="wheel-35">
			<origin xyz="0.1804072528569437 0.7323625 0.25773058044729175"/>
			<geometry>
				<mesh filename="textured_objs/original-17.obj"/>
			</geometry>
		</visual>
		<collision>
			<origin xyz="0.1804072528569437 0.7323625 0.25773058044729175"/>
			<geometry>
				<mesh filename="textured_objs/original-17.obj"/>
			</geometry>
		</collision>
	</link>
	<joint name="joint_1" type="continuous">
		<origin xyz="0.08487274714305626 -0.7323625 -0.03722758044729174"/>
		<axis xyz="-0.8192381052209088 0 0.5734535089735308"/>
		<child link="link_1"/>
		<parent link="link_0"/>
	</joint>
	<link name="link_2">
		<visual name="caster_stem-32">
			<origin xyz="-0.322162 0 0.220503"/>
			<geometry>
				<mesh filename="textured_objs/original-8.obj"/>
			</geometry>
		</visual>
		<collision>
			<origin xyz="-0.322162 0 0.220503"/>
			<geometry>
				<mesh filename="textured_objs/original-8.obj"/>
			</geometry>
		</collision>
	</link>
	<joint name="joint_2" type="continuous">
		<origin xyz="0.322162 0 -0.220503"/>
		<axis xyz="0 1 0"/>
		<child link="link_2"/>
		<parent link="link_11"/>
	</joint>
	<link name="link_3">
		<visual name="wheel-33">
			<origin xyz="-0.2110717855963781 0.7323625 0.2814667373530247"/>
			<geometry>
				<mesh filename="textured_objs/original-14.obj"/>
			</geometry>
		</visual>
		<collision>
			<origin xyz="-0.2110717855963781 0.7323625 0.2814667373530247"/>
			<geometry>
				<mesh filename="textured_objs/original-14.obj"/>
			</geometry>
		</collision>
	</link>
	<joint name="joint_3" type="continuous">
		<origin xyz="-0.1110902144036219 -0.7323625 -0.06096373735302468"/>
		<axis xyz="-0.8000385699131759 0 -0.5999485700051966"/>
		<child link="link_3"/>
		<parent link="link_2"/>
	</joint>
	<link name="link_4">
		<visual name="caster_stem-30">
			<origin xyz="-0.503871 0 -0.338314"/>
			<geometry>
				<mesh filename="textured_objs/original-9.obj"/>
			</geometry>
		</visual>
		<collision>
			<origin xyz="-0.503871 0 -0.338314"/>
			<geometry>
				<mesh filename="textured_objs/original-9.obj"/>
			</geometry>
		</collision>
	</link>
	<joint name="joint_4" type="continuous">
		<origin xyz="0.503871 0 0.338314"/>
		<axis xyz="0 1 0"/>
		<child link="link_4"/>
		<parent link="link_11"/>
	</joint>
	<link name="link_5">
		<visual name="wheel-31">
			<origin xyz="-0.5380192715980543 0.7323625 -0.17933976846705507"/>
			<geometry>
				<mesh filename="textured_objs/original-15.obj"/>
			</geometry>
		</visual>
		<collision>
			<origin xyz="-0.5380192715980543 0.7323625 -0.17933976846705507"/>
			<geometry>
				<mesh filename="textured_objs/original-15.obj"/>
			</geometry>
		</collision>
	</link>
	<joint name="joint_5" type="continuous">
		<origin xyz="0.034148271598054336 -0.7323625 -0.15897423153294493"/>
		<axis xyz="0.3162277660168369 0 -0.9486832980505142"/>
		<child link="link_5"/>
		<parent link="link_4"/>
	</joint>
	<link name="link_6">
		<visual name="caster_stem-28">
			<origin xyz="-0.028440999999999998 0 -0.683685"/>
			<geometry>
				<mesh filename="textured_objs/original-10.obj"/>
			</geometry>
		</visual>
		<collision>
			<origin xyz="-0.028440999999999998 0 -0.683685"/>
			<geometry>
				<mesh filename="textured_objs/original-10.obj"/>
			</geometry>
		</collision>
	</link>
	<joint name="joint_6" type="continuous">
		<origin xyz="0.028440999999999998 0 0.683685"/>
		<axis xyz="0 1 0"/>
		<child link="link_6"/>
		<parent link="link_11"/>
	</joint>
	<link name="link_7">
		<visual name="wheel-29">
			<origin xyz="0 0.7323625 -0.665846004274913"/>
			<geometry>
				<mesh filename="textured_objs/original-16.obj"/>
			</geometry>
		</visual>
		<collision>
			<origin xyz="0 0.7323625 -0.665846004274913"/>
			<geometry>
				<mesh filename="textured_objs/original-16.obj"/>
			</geometry>
		</collision>
	</link>
	<joint name="joint_7" type="continuous">
		<origin xyz="-0.028440999999999998 -0.7323625 -0.01783899572508696"/>
		<axis xyz="1 0 0"/>
		<child link="link_7"/>
		<parent link="link_6"/>
	</joint>
	<link name="link_8">
		<visual name="wheel-26">
			<origin xyz="0.48682547228628265 0.7323625 -0.162275167624316"/>
			<geometry>
				<mesh filename="textured_objs/original-18.obj"/>
			</geometry>
		</visual>
		<collision>
			<origin xyz="0.48682547228628265 0.7323625 -0.162275167624316"/>
			<geometry>
				<mesh filename="textured_objs/original-18.obj"/>
			</geometry>
		</collision>
	</link>
	<joint name="joint_8" type="continuous">
		<origin xyz="-0.039836472286282676 -0.7323625 -0.176038832375684"/>
		<axis xyz="0.316227766016838 0 0.9486832980505139"/>
		<child link="link_8"/>
		<parent link="link_9"/>
	</joint>
	<link name="link_9">
		<visual name="caster_stem-27">
			<origin xyz="0.44698899999999997 0 -0.338314"/>
			<geometry>
				<mesh filename="textured_objs/original-12.obj"/>
			</geometry>
		</visual>
		<collision>
			<origin xyz="0.44698899999999997 0 -0.338314"/>
			<geometry>
				<mesh filename="textured_objs/original-12.obj"/>
			</geometry>
		</collision>
	</link>
	<joint name="joint_9" type="continuous">
		<origin xyz="-0.44698899999999997 0 0.338314"/>
		<axis xyz="0 1 0"/>
		<child link="link_9"/>
		<parent link="link_11"/>
	</joint>
	<link name="link_10">
		<visual name="back_soft_surface-54">
			<origin xyz="-0.026605842262506466 0 -0.18576659771800028"/>
			<geometry>
				<mesh filename="textured_objs/original-28.obj"/>
			</geometry>
		</visual>
		<visual name="back_soft_surface-54">
			<origin xyz="-0.026605842262506466 0 -0.18576659771800028"/>
			<geometry>
				<mesh filename="textured_objs/original-29.obj"/>
			</geometry>
		</visual>
		<visual name="back_soft_surface-54">
			<origin xyz="-0.026605842262506466 0 -0.18576659771800028"/>
			<geometry>
				<mesh filename="textured_objs/original-30.obj"/>
			</geometry>
		</visual>
		<visual name="back_soft_surface-54">
			<origin xyz="-0.026605842262506466 0 -0.18576659771800028"/>
			<geometry>
				<mesh filename="textured_objs/original-41.obj"/>
			</geometry>
		</visual>
		<visual name="back_soft_surface-54">
			<origin xyz="-0.026605842262506466 0 -0.18576659771800028"/>
			<geometry>
				<mesh filename="textured_objs/original-33.obj"/>
			</geometry>
		</visual>
		<visual name="back_soft_surface-54">
			<origin xyz="-0.026605842262506466 0 -0.18576659771800028"/>
			<geometry>
				<mesh filename="textured_objs/original-38.obj"/>
			</geometry>
		</visual>
		<visual name="back_soft_surface-54">
			<origin xyz="-0.026605842262506466 0 -0.18576659771800028"/>
			<geometry>
				<mesh filename="textured_objs/original-31.obj"/>
			</geometry>
		</visual>
		<visual name="back_soft_surface-54">
			<origin xyz="-0.026605842262506466 0 -0.18576659771800028"/>
			<geometry>
				<mesh filename="textured_objs/original-40.obj"/>
			</geometry>
		</visual>
		<visual name="back_soft_surface-54">
			<origin xyz="-0.026605842262506466 0 -0.18576659771800028"/>
			<geometry>
				<mesh filename="textured_objs/original-39.obj"/>
			</geometry>
		</visual>
		<visual name="back_soft_surface-54">
			<origin xyz="-0.026605842262506466 0 -0.18576659771800028"/>
			<geometry>
				<mesh filename="textured_objs/original-32.obj"/>
			</geometry>
		</visual>
		<visual name="back_frame_vertical_bar-50">
			<origin xyz="-0.026605842262506466 0 -0.18576659771800028"/>
			<geometry>
				<mesh filename="textured_objs/new-9.obj"/>
			</geometry>
		</visual>
		<visual name="back_frame_vertical_bar-51">
			<origin xyz="-0.026605842262506466 0 -0.18576659771800028"/>
			<geometry>
				<mesh filename="textured_objs/new-11.obj"/>
			</geometry>
		</visual>
		<visual name="armrest_soft_surface-45">
			<origin xyz="-0.026605842262506466 0 -0.18576659771800028"/>
			<geometry>
				<mesh filename="textured_objs/original-23.obj"/>
			</geometry>
		</visual>
		<visual name="arm_vertical_bar-46">
			<origin xyz="-0.026605842262506466 0 -0.18576659771800028"/>
			<geometry>
				<mesh filename="textured_objs/new-13.obj"/>
			</geometry>
		</visual>
		<visual name="arm_horizontal_bar-47">
			<origin xyz="-0.026605842262506466 0 -0.18576659771800028"/>
			<geometry>
				<mesh filename="textured_objs/new-12.obj"/>
			</geometry>
		</visual>
		<visual name="arm_horizontal_bar-47">
			<origin xyz="-0.026605842262506466 0 -0.18576659771800028"/>
			<geometry>
				<mesh filename="textured_objs/original-25.obj"/>
			</geometry>
		</visual>
		<visual name="arm_horizontal_bar-47">
			<origin xyz="-0.026605842262506466 0 -0.18576659771800028"/>
			<geometry>
				<mesh filename="textured_objs/original-24.obj"/>
			</geometry>
		</visual>
		<visual name="armrest_soft_surface-42">
			<origin xyz="-0.026605842262506466 0 -0.18576659771800028"/>
			<geometry>
				<mesh filename="textured_objs/original-22.obj"/>
			</geometry>
		</visual>
		<visual name="arm_vertical_bar-43">
			<origin xyz="-0.026605842262506466 0 -0.18576659771800028"/>
			<geometry>
				<mesh filename="textured_objs/new-7.obj"/>
			</geometry>
		</visual>
		<visual name="arm_horizontal_bar-44">
			<origin xyz="-0.026605842262506466 0 -0.18576659771800028"/>
			<geometry>
				<mesh filename="textured_objs/new-8.obj"/>
			</geometry>
		</visual>
		<visual name="seat_soft_surface-38">
			<origin xyz="-0.026605842262506466 0 -0.18576659771800028"/>
			<geometry>
				<mesh filename="textured_objs/original-34.obj"/>
			</geometry>
		</visual>
		<visual name="seat_soft_surface-38">
			<origin xyz="-0.026605842262506466 0 -0.18576659771800028"/>
			<geometry>
				<mesh filename="textured_objs/original-35.obj"/>
			</geometry>
		</visual>
		<visual name="seat_soft_surface-38">
			<origin xyz="-0.026605842262506466 0 -0.18576659771800028"/>
			<geometry>
				<mesh filename="textured_objs/original-36.obj"/>
			</geometry>
		</visual>
		<visual name="seat_soft_surface-38">
			<origin xyz="-0.026605842262506466 0 -0.18576659771800028"/>
			<geometry>
				<mesh filename="textured_objs/original-37.obj"/>
			</geometry>
		</visual>
		<visual name="seat_soft_surface-38">
			<origin xyz="-0.026605842262506466 0 -0.18576659771800028"/>
			<geometry>
				<mesh filename="textured_objs/original-20.obj"/>
			</geometry>
		</visual>
		<visual name="seat_support-37">
			<origin xyz="-0.026605842262506466 0 -0.18576659771800028"/>
			<geometry>
				<mesh filename="textured_objs/original-42.obj"/>
			</geometry>
		</visual>
		<visual name="seat_frame_vertical_bar-40">
			<origin xyz="-0.026605842262506466 0 -0.18576659771800028"/>
			<geometry>
				<mesh filename="textured_objs/new-10.obj"/>
			</geometry>
		</visual>
		<visual name="seat_frame_vertical_bar-41">
			<origin xyz="-0.026605842262506466 0 -0.18576659771800028"/>
			<geometry>
				<mesh filename="textured_objs/new-6.obj"/>
			</geometry>
		</visual>
		<visual name="central_support-11">
			<origin xyz="-0.026605842262506466 0 -0.18576659771800028"/>
			<geometry>
				<mesh filename="textured_objs/original-7.obj"/>
			</geometry>
		</visual>
		<visual name="seat_connector-13">
			<origin xyz="-0.026605842262506466 0 -0.18576659771800028"/>
			<geometry>
				<mesh filename="textured_objs/original-21.obj"/>
			</geometry>
		</visual>
		<collision>
			<origin xyz="-0.026605842262506466 0 -0.18576659771800028"/>
			<geometry>
				<mesh filename="textured_objs/original-28.obj"/>
			</geometry>
		</collision>
		<collision>
			<origin xyz="-0.026605842262506466 0 -0.18576659771800028"/>
			<geometry>
				<mesh filename="textured_objs/original-29.obj"/>
			</geometry>
		</collision>
		<collision>
			<origin xyz="-0.026605842262506466 0 -0.18576659771800028"/>
			<geometry>
				<mesh filename="textured_objs/original-30.obj"/>
			</geometry>
		</collision>
		<collision>
			<origin xyz="-0.026605842262506466 0 -0.18576659771800028"/>
			<geometry>
				<mesh filename="textured_objs/original-41.obj"/>
			</geometry>
		</collision>
		<collision>
			<origin xyz="-0.026605842262506466 0 -0.18576659771800028"/>
			<geometry>
				<mesh filename="textured_objs/original-33.obj"/>
			</geometry>
		</collision>
		<collision>
			<origin xyz="-0.026605842262506466 0 -0.18576659771800028"/>
			<geometry>
				<mesh filename="textured_objs/original-38.obj"/>
			</geometry>
		</collision>
		<collision>
			<origin xyz="-0.026605842262506466 0 -0.18576659771800028"/>
			<geometry>
				<mesh filename="textured_objs/original-31.obj"/>
			</geometry>
		</collision>
		<collision>
			<origin xyz="-0.026605842262506466 0 -0.18576659771800028"/>
			<geometry>
				<mesh filename="textured_objs/original-40.obj"/>
			</geometry>
		</collision>
		<collision>
			<origin xyz="-0.026605842262506466 0 -0.18576659771800028"/>
			<geometry>
				<mesh filename="textured_objs/original-39.obj"/>
			</geometry>
		</collision>
		<collision>
			<origin xyz="-0.026605842262506466 0 -0.18576659771800028"/>
			<geometry>
				<mesh filename="textured_objs/original-32.obj"/>
			</geometry>
		</collision>
		<collision>
			<origin xyz="-0.026605842262506466 0 -0.18576659771800028"/>
			<geometry>
				<mesh filename="textured_objs/new-9.obj"/>
			</geometry>
		</collision>
		<collision>
			<origin xyz="-0.026605842262506466 0 -0.18576659771800028"/>
			<geometry>
				<mesh filename="textured_objs/new-11.obj"/>
			</geometry>
		</collision>
		<collision>
			<origin xyz="-0.026605842262506466 0 -0.18576659771800028"/>
			<geometry>
				<mesh filename="textured_objs/original-23.obj"/>
			</geometry>
		</collision>
		<collision>
			<origin xyz="-0.026605842262506466 0 -0.18576659771800028"/>
			<geometry>
				<mesh filename="textured_objs/new-13.obj"/>
			</geometry>
		</collision>
		<collision>
			<origin xyz="-0.026605842262506466 0 -0.18576659771800028"/>
			<geometry>
				<mesh filename="textured_objs/new-12.obj"/>
			</geometry>
		</collision>
		<collision>
			<origin xyz="-0.026605842262506466 0 -0.18576659771800028"/>
			<geometry>
				<mesh filename="textured_objs/original-25.obj"/>
			</geometry>
		</collision>
		<collision>
			<origin xyz="-0.026605842262506466 0 -0.18576659771800028"/>
			<geometry>
				<mesh filename="textured_objs/original-24.obj"/>
			</geometry>
		</collision>
		<collision>
			<origin xyz="-0.026605842262506466 0 -0.18576659771800028"/>
			<geometry>
				<mesh filename="textured_objs/original-22.obj"/>
			</geometry>
		</collision>
		<collision>
			<origin xyz="-0.026605842262506466 0 -0.18576659771800028"/>
			<geometry>
				<mesh filename="textured_objs/new-7.obj"/>
			</geometry>
		</collision>
		<collision>
			<origin xyz="-0.026605842262506466 0 -0.18576659771800028"/>
			<geometry>
				<mesh filename="textured_objs/new-8.obj"/>
			</geometry>
		</collision>
		<collision>
			<origin xyz="-0.026605842262506466 0 -0.18576659771800028"/>
			<geometry>
				<mesh filename="textured_objs/original-34.obj"/>
			</geometry>
		</collision>
		<collision>
			<origin xyz="-0.026605842262506466 0 -0.18576659771800028"/>
			<geometry>
				<mesh filename="textured_objs/original-35.obj"/>
			</geometry>
		</collision>
		<collision>
			<origin xyz="-0.026605842262506466 0 -0.18576659771800028"/>
			<geometry>
				<mesh filename="textured_objs/original-36.obj"/>
			</geometry>
		</collision>
		<collision>
			<origin xyz="-0.026605842262506466 0 -0.18576659771800028"/>
			<geometry>
				<mesh filename="textured_objs/original-37.obj"/>
			</geometry>
		</collision>
		<collision>
			<origin xyz="-0.026605842262506466 0 -0.18576659771800028"/>
			<geometry>
				<mesh filename="textured_objs/original-20.obj"/>
			</geometry>
		</collision>
		<collision>
			<origin xyz="-0.026605842262506466 0 -0.18576659771800028"/>
			<geometry>
				<mesh filename="textured_objs/original-42.obj"/>
			</geometry>
		</collision>
		<collision>
			<origin xyz="-0.026605842262506466 0 -0.18576659771800028"/>
			<geometry>
				<mesh filename="textured_objs/new-10.obj"/>
			</geometry>
		</collision>
		<collision>
			<origin xyz="-0.026605842262506466 0 -0.18576659771800028"/>
			<geometry>
				<mesh filename="textured_objs/new-6.obj"/>
			</geometry>
		</collision>
		<collision>
			<origin xyz="-0.026605842262506466 0 -0.18576659771800028"/>
			<geometry>
				<mesh filename="textured_objs/original-7.obj"/>
			</geometry>
		</collision>
		<collision>
			<origin xyz="-0.026605842262506466 0 -0.18576659771800028"/>
			<geometry>
				<mesh filename="textured_objs/original-21.obj"/>
			</geometry>
		</collision>
	</link>
	<joint name="joint_10" type="continuous">
		<origin xyz="0.0 0 0.0"/>
		<axis xyz="0 1 0"/>
		<child link="link_10"/>
		<parent link="link_10_helper"/>
	</joint>
	<link name="link_11">
		<visual name="central_support-10">
			<origin xyz="0 0 0"/>
			<geometry>
				<mesh filename="textured_objs/new-5.obj"/>
			</geometry>
		</visual>
		<visual name="leg-14">
			<origin xyz="0 0 0"/>
			<geometry>
				<mesh filename="textured_objs/new-4.obj"/>
			</geometry>
		</visual>
		<visual name="leg-15">
			<origin xyz="0 0 0"/>
			<geometry>
				<mesh filename="textured_objs/new-3.obj"/>
			</geometry>
		</visual>
		<visual name="leg-16">
			<origin xyz="0 0 0"/>
			<geometry>
				<mesh filename="textured_objs/new-2.obj"/>
			</geometry>
		</visual>
		<visual name="leg-17">
			<origin xyz="0 0 0"/>
			<geometry>
				<mesh filename="textured_objs/new-1.obj"/>
			</geometry>
		</visual>
		<visual name="leg-18">
			<origin xyz="0 0 0"/>
			<geometry>
				<mesh filename="textured_objs/new-0.obj"/>
			</geometry>
		</visual>
		<collision>
			<origin xyz="0 0 0"/>
			<geometry>
				<mesh filename="textured_objs/new-5.obj"/>
			</geometry>
		</collision>
		<collision>
			<origin xyz="0 0 0"/>
			<geometry>
				<mesh filename="textured_objs/new-4.obj"/>
			</geometry>
		</collision>
		<collision>
			<origin xyz="0 0 0"/>
			<geometry>
				<mesh filename="textured_objs/new-3.obj"/>
			</geometry>
		</collision>
		<collision>
			<origin xyz="0 0 0"/>
			<geometry>
				<mesh filename="textured_objs/new-2.obj"/>
			</geometry>
		</collision>
		<collision>
			<origin xyz="0 0 0"/>
			<geometry>
				<mesh filename="textured_objs/new-1.obj"/>
			</geometry>
		</collision>
		<collision>
			<origin xyz="0 0 0"/>
			<geometry>
				<mesh filename="textured_objs/new-0.obj"/>
			</geometry>
		</collision>
	</link>
	<joint name="joint_11" type="fixed">
		<origin rpy="1.570796326794897 0 -1.570796326794897" xyz="0 0 0"/>
		<child link="link_11"/>
		<parent link="base"/>
	</joint>
	<link name="link_10_helper"/>
	<joint name="joint_12" type="prismatic">
		<origin xyz="0.026605842262506466 0 0.18576659771800028"/>
		<axis xyz="0 -1 0"/>
		<child link="link_10_helper"/>
		<parent link="link_11"/>
		<limit lower="0" upper="0.06000000000000005"/>
	</joint>
</robot>
