<?xml version="1.0" ?>
<robot name="partnet_fd244782842c611b6443e5551f9d3958">
	<link name="base"/>
	<link name="link_0">
		<visual name="lever-30">
			<origin xyz="-0.23201620674226467 0.10494929997483547 0"/>
			<geometry>
				<mesh filename="textured_objs/original-17.obj"/>
			</geometry>
		</visual>
		<visual name="lever-30">
			<origin xyz="-0.23201620674226467 0.10494929997483547 0"/>
			<geometry>
				<mesh filename="textured_objs/original-18.obj"/>
			</geometry>
		</visual>
		<collision>
			<origin xyz="-0.23201620674226467 0.10494929997483547 0"/>
			<geometry>
				<mesh filename="textured_objs/original-17.obj"/>
			</geometry>
		</collision>
		<collision>
			<origin xyz="-0.23201620674226467 0.10494929997483547 0"/>
			<geometry>
				<mesh filename="textured_objs/original-18.obj"/>
			</geometry>
		</collision>
	</link>
	<joint name="joint_0" type="revolute">
		<origin xyz="0.21791199547693807 -0.10494929997483547 -0.1323726340427047"/>
		<axis xyz="0 0 -1"/>
		<child link="link_0"/>
		<parent link="link_12"/>
		<limit lower="-0.19198621771937624" upper="0.2792526803190927"/>
	</joint>
	<link name="link_1">
		<visual name="lever-31">
			<origin xyz="0.19220726683642655 0.09702514949603697 0"/>
			<geometry>
				<mesh filename="textured_objs/original-20.obj"/>
			</geometry>
		</visual>
		<visual name="lever-31">
			<origin xyz="0.19220726683642655 0.09702514949603697 0"/>
			<geometry>
				<mesh filename="textured_objs/original-21.obj"/>
			</geometry>
		</visual>
		<collision>
			<origin xyz="0.19220726683642655 0.09702514949603697 0"/>
			<geometry>
				<mesh filename="textured_objs/original-20.obj"/>
			</geometry>
		</collision>
		<collision>
			<origin xyz="0.19220726683642655 0.09702514949603697 0"/>
			<geometry>
				<mesh filename="textured_objs/original-21.obj"/>
			</geometry>
		</collision>
	</link>
	<joint name="joint_1" type="revolute">
		<origin xyz="-0.20631147810175315 -0.09702514949603697 -0.1323726340427047"/>
		<axis xyz="0 0 1"/>
		<child link="link_1"/>
		<parent link="link_12"/>
		<limit lower="-0.2617993877991494" upper="0.17453292519943295"/>
	</joint>
	<link name="link_2">
		<visual name="caster_stem-28">
			<origin xyz="0.44596691387900356 0 -0.0816165"/>
			<geometry>
				<mesh filename="textured_objs/original-14.obj"/>
			</geometry>
		</visual>
		<collision>
			<origin xyz="0.44596691387900356 0 -0.0816165"/>
			<geometry>
				<mesh filename="textured_objs/original-14.obj"/>
			</geometry>
		</collision>
	</link>
	<joint name="joint_2" type="continuous">
		<origin xyz="-0.44596691387900356 0 0.0816165"/>
		<axis xyz="0 1 0"/>
		<child link="link_2"/>
		<parent link="link_13"/>
	</joint>
	<link name="link_3">
		<visual name="wheel-29">
			<origin xyz="0 0.7571262728211829 -0.0768900157799619"/>
			<geometry>
				<mesh filename="textured_objs/original-15.obj"/>
			</geometry>
		</visual>
		<collision>
			<origin xyz="0 0.7571262728211829 -0.0768900157799619"/>
			<geometry>
				<mesh filename="textured_objs/original-15.obj"/>
			</geometry>
		</collision>
	</link>
	<joint name="joint_3" type="continuous">
		<origin xyz="0.44596691387900356 -0.7571262728211829 -0.004726484220038088"/>
		<axis xyz="-1 0 0"/>
		<child link="link_3"/>
		<parent link="link_2"/>
	</joint>
	<link name="link_4">
		<visual name="caster_stem-26">
			<origin xyz="0.0652675 0 0.3489935"/>
			<geometry>
				<mesh filename="textured_objs/original-26.obj"/>
			</geometry>
		</visual>
		<collision>
			<origin xyz="0.0652675 0 0.3489935"/>
			<geometry>
				<mesh filename="textured_objs/original-26.obj"/>
			</geometry>
		</collision>
	</link>
	<joint name="joint_4" type="continuous">
		<origin xyz="-0.0652675 0 -0.3489935"/>
		<axis xyz="0 1 0"/>
		<child link="link_4"/>
		<parent link="link_13"/>
	</joint>
	<link name="link_5">
		<visual name="wheel-27">
			<origin xyz="0 0.7571262728211829 0.35372001577996187"/>
			<geometry>
				<mesh filename="textured_objs/original-27.obj"/>
			</geometry>
		</visual>
		<collision>
			<origin xyz="0 0.7571262728211829 0.35372001577996187"/>
			<geometry>
				<mesh filename="textured_objs/original-27.obj"/>
			</geometry>
		</collision>
	</link>
	<joint name="joint_5" type="continuous">
		<origin xyz="0.0652675 -0.7571262728211829 -0.0047265157799618596"/>
		<axis xyz="1 0 0"/>
		<child link="link_5"/>
		<parent link="link_4"/>
	</joint>
	<link name="link_6">
		<visual name="caster_stem-24">
			<origin xyz="-0.4470952812818848 0 0.0764365"/>
			<geometry>
				<mesh filename="textured_objs/original-29.obj"/>
			</geometry>
		</visual>
		<collision>
			<origin xyz="-0.4470952812818848 0 0.0764365"/>
			<geometry>
				<mesh filename="textured_objs/original-29.obj"/>
			</geometry>
		</collision>
	</link>
	<joint name="joint_6" type="continuous">
		<origin xyz="0.4470952812818848 0 -0.0764365"/>
		<axis xyz="0 1 0"/>
		<child link="link_6"/>
		<parent link="link_13"/>
	</joint>
	<link name="link_7">
		<visual name="wheel-25">
			<origin xyz="0 0.7571263117914265 0.08116331179142651"/>
			<geometry>
				<mesh filename="textured_objs/original-30.obj"/>
			</geometry>
		</visual>
		<collision>
			<origin xyz="0 0.7571263117914265 0.08116331179142651"/>
			<geometry>
				<mesh filename="textured_objs/original-30.obj"/>
			</geometry>
		</collision>
	</link>
	<joint name="joint_7" type="continuous">
		<origin xyz="-0.4470952812818848 -0.7571263117914265 -0.004726811791426505"/>
		<axis xyz="1 0 0"/>
		<child link="link_7"/>
		<parent link="link_6"/>
	</joint>
	<link name="link_8">
		<visual name="caster_stem-22">
			<origin xyz="-0.35800308612099646 0 -0.47443149999999995"/>
			<geometry>
				<mesh filename="textured_objs/original-32.obj"/>
			</geometry>
		</visual>
		<collision>
			<origin xyz="-0.35800308612099646 0 -0.47443149999999995"/>
			<geometry>
				<mesh filename="textured_objs/original-32.obj"/>
			</geometry>
		</collision>
	</link>
	<joint name="joint_8" type="continuous">
		<origin xyz="0.35800308612099646 0 0.47443149999999995"/>
		<axis xyz="0 1 0"/>
		<child link="link_8"/>
		<parent link="link_13"/>
	</joint>
	<link name="link_9">
		<visual name="wheel-23">
			<origin xyz="0 0.7571262707437332 -0.469705"/>
			<geometry>
				<mesh filename="textured_objs/original-33.obj"/>
			</geometry>
		</visual>
		<collision>
			<origin xyz="0 0.7571262707437332 -0.469705"/>
			<geometry>
				<mesh filename="textured_objs/original-33.obj"/>
			</geometry>
		</collision>
	</link>
	<joint name="joint_9" type="continuous">
		<origin xyz="-0.35800308612099646 -0.7571262707437332 -0.004726499999999967"/>
		<axis xyz="1 0 0"/>
		<child link="link_9"/>
		<parent link="link_8"/>
	</joint>
	<link name="link_10">
		<visual name="caster_stem-20">
			<origin xyz="0.2059095 0 -0.5647212812818848"/>
			<geometry>
				<mesh filename="textured_objs/original-23.obj"/>
			</geometry>
		</visual>
		<collision>
			<origin xyz="0.2059095 0 -0.5647212812818848"/>
			<geometry>
				<mesh filename="textured_objs/original-23.obj"/>
			</geometry>
		</collision>
	</link>
	<joint name="joint_10" type="continuous">
		<origin xyz="-0.2059095 0 0.5647212812818848"/>
		<axis xyz="0 1 0"/>
		<child link="link_10"/>
		<parent link="link_13"/>
	</joint>
	<link name="link_11">
		<visual name="wheel-21">
			<origin xyz="0 0.757126389225537 -0.559994610774463"/>
			<geometry>
				<mesh filename="textured_objs/original-24.obj"/>
			</geometry>
		</visual>
		<collision>
			<origin xyz="0 0.757126389225537 -0.559994610774463"/>
			<geometry>
				<mesh filename="textured_objs/original-24.obj"/>
			</geometry>
		</collision>
	</link>
	<joint name="joint_11" type="continuous">
		<origin xyz="0.2059095 -0.757126389225537 -0.004726670507421815"/>
		<axis xyz="1 0 0"/>
		<child link="link_11"/>
		<parent link="link_10"/>
	</joint>
	<link name="link_12">
		<visual name="arm_holistic_frame-37">
			<origin xyz="-0.014104211265326603 0 -0.1323726340427047"/>
			<geometry>
				<mesh filename="textured_objs/original-5.obj"/>
			</geometry>
		</visual>
		<visual name="arm_holistic_frame-36">
			<origin xyz="-0.014104211265326603 0 -0.1323726340427047"/>
			<geometry>
				<mesh filename="textured_objs/original-6.obj"/>
			</geometry>
		</visual>
		<visual name="back_soft_surface-40">
			<origin xyz="-0.014104211265326603 0 -0.1323726340427047"/>
			<geometry>
				<mesh filename="textured_objs/original-4.obj"/>
			</geometry>
		</visual>
		<visual name="back_soft_surface-41">
			<origin xyz="-0.014104211265326603 0 -0.1323726340427047"/>
			<geometry>
				<mesh filename="textured_objs/original-3.obj"/>
			</geometry>
		</visual>
		<visual name="back_support-39">
			<origin xyz="-0.014104211265326603 0 -0.1323726340427047"/>
			<geometry>
				<mesh filename="textured_objs/new-7.obj"/>
			</geometry>
		</visual>
		<visual name="seat_soft_surface-35">
			<origin xyz="-0.014104211265326603 0 -0.1323726340427047"/>
			<geometry>
				<mesh filename="textured_objs/original-11.obj"/>
			</geometry>
		</visual>
		<visual name="seat_support-34">
			<origin xyz="-0.014104211265326603 0 -0.1323726340427047"/>
			<geometry>
				<mesh filename="textured_objs/new-6.obj"/>
			</geometry>
		</visual>
		<visual name="mounting_plate-32">
			<origin xyz="-0.014104211265326603 0 -0.1323726340427047"/>
			<geometry>
				<mesh filename="textured_objs/original-34.obj"/>
			</geometry>
		</visual>
		<collision>
			<origin xyz="-0.014104211265326603 0 -0.1323726340427047"/>
			<geometry>
				<mesh filename="textured_objs/original-5.obj"/>
			</geometry>
		</collision>
		<collision>
			<origin xyz="-0.014104211265326603 0 -0.1323726340427047"/>
			<geometry>
				<mesh filename="textured_objs/original-6.obj"/>
			</geometry>
		</collision>
		<collision>
			<origin xyz="-0.014104211265326603 0 -0.1323726340427047"/>
			<geometry>
				<mesh filename="textured_objs/original-4.obj"/>
			</geometry>
		</collision>
		<collision>
			<origin xyz="-0.014104211265326603 0 -0.1323726340427047"/>
			<geometry>
				<mesh filename="textured_objs/original-3.obj"/>
			</geometry>
		</collision>
		<collision>
			<origin xyz="-0.014104211265326603 0 -0.1323726340427047"/>
			<geometry>
				<mesh filename="textured_objs/new-7.obj"/>
			</geometry>
		</collision>
		<collision>
			<origin xyz="-0.014104211265326603 0 -0.1323726340427047"/>
			<geometry>
				<mesh filename="textured_objs/original-11.obj"/>
			</geometry>
		</collision>
		<collision>
			<origin xyz="-0.014104211265326603 0 -0.1323726340427047"/>
			<geometry>
				<mesh filename="textured_objs/new-6.obj"/>
			</geometry>
		</collision>
		<collision>
			<origin xyz="-0.014104211265326603 0 -0.1323726340427047"/>
			<geometry>
				<mesh filename="textured_objs/original-34.obj"/>
			</geometry>
		</collision>
	</link>
	<joint name="joint_12" type="continuous">
		<origin xyz="0.0 0 0.0"/>
		<axis xyz="0 1 0"/>
		<child link="link_12"/>
		<parent link="link_12_helper"/>
	</joint>
	<link name="link_13">
		<visual name="central_support-7">
			<origin xyz="0 0 0"/>
			<geometry>
				<mesh filename="textured_objs/new-5.obj"/>
			</geometry>
		</visual>
		<visual name="leg-10">
			<origin xyz="0 0 0"/>
			<geometry>
				<mesh filename="textured_objs/new-0.obj"/>
			</geometry>
		</visual>
		<visual name="leg-11">
			<origin xyz="0 0 0"/>
			<geometry>
				<mesh filename="textured_objs/new-4.obj"/>
			</geometry>
		</visual>
		<visual name="leg-12">
			<origin xyz="0 0 0"/>
			<geometry>
				<mesh filename="textured_objs/new-3.obj"/>
			</geometry>
		</visual>
		<visual name="leg-13">
			<origin xyz="0 0 0"/>
			<geometry>
				<mesh filename="textured_objs/new-2.obj"/>
			</geometry>
		</visual>
		<visual name="leg-14">
			<origin xyz="0 0 0"/>
			<geometry>
				<mesh filename="textured_objs/new-1.obj"/>
			</geometry>
		</visual>
		<collision>
			<origin xyz="0 0 0"/>
			<geometry>
				<mesh filename="textured_objs/new-5.obj"/>
			</geometry>
		</collision>
		<collision>
			<origin xyz="0 0 0"/>
			<geometry>
				<mesh filename="textured_objs/new-0.obj"/>
			</geometry>
		</collision>
		<collision>
			<origin xyz="0 0 0"/>
			<geometry>
				<mesh filename="textured_objs/new-4.obj"/>
			</geometry>
		</collision>
		<collision>
			<origin xyz="0 0 0"/>
			<geometry>
				<mesh filename="textured_objs/new-3.obj"/>
			</geometry>
		</collision>
		<collision>
			<origin xyz="0 0 0"/>
			<geometry>
				<mesh filename="textured_objs/new-2.obj"/>
			</geometry>
		</collision>
		<collision>
			<origin xyz="0 0 0"/>
			<geometry>
				<mesh filename="textured_objs/new-1.obj"/>
			</geometry>
		</collision>
	</link>
	<joint name="joint_13" type="fixed">
		<origin rpy="1.570796326794897 0 -1.570796326794897" xyz="0 0 0"/>
		<child link="link_13"/>
		<parent link="base"/>
	</joint>
	<link name="link_12_helper"/>
	<joint name="joint_14" type="prismatic">
		<origin xyz="0.014104211265326603 0 0.1323726340427047"/>
		<axis xyz="0 -1 0"/>
		<child link="link_12_helper"/>
		<parent link="link_13"/>
		<limit lower="0" upper="0.1"/>
	</joint>
</robot>
