<?xml version="1.0" ?>
<robot name="partnet_10d174a00639990492d9da2668ec34c">
	<link name="base"/>
	<link name="link_0">
		<visual name="caster_stem-33">
			<origin xyz="-0.0069935 0 -0.487691"/>
			<geometry>
				<mesh filename="textured_objs/original-26.obj"/>
			</geometry>
		</visual>
		<collision>
			<origin xyz="-0.0069935 0 -0.487691"/>
			<geometry>
				<mesh filename="textured_objs/original-26.obj"/>
			</geometry>
		</collision>
	</link>
	<joint name="joint_0" type="continuous">
		<origin xyz="0.0069935 0 0.487691"/>
		<axis xyz="0 1 0"/>
		<child link="link_0"/>
		<parent link="link_16"/>
	</joint>
	<link name="link_1">
		<visual name="wheel-34">
			<origin xyz="0 0.6648493966799938 -0.5347208123651194"/>
			<geometry>
				<mesh filename="textured_objs/original-25.obj"/>
			</geometry>
		</visual>
		<collision>
			<origin xyz="0 0.6648493966799938 -0.5347208123651194"/>
			<geometry>
				<mesh filename="textured_objs/original-25.obj"/>
			</geometry>
		</collision>
	</link>
	<joint name="joint_1" type="continuous">
		<origin xyz="-0.0069935 -0.6648493966799938 0.04702981236511938"/>
		<axis xyz="1 0 0"/>
		<child link="link_1"/>
		<parent link="link_0"/>
	</joint>
	<link name="link_2">
		<visual name="wheel-35">
			<origin xyz="0 0.6648493966799938 -0.5347208123651194"/>
			<geometry>
				<mesh filename="textured_objs/original-24.obj"/>
			</geometry>
		</visual>
		<collision>
			<origin xyz="0 0.6648493966799938 -0.5347208123651194"/>
			<geometry>
				<mesh filename="textured_objs/original-24.obj"/>
			</geometry>
		</collision>
	</link>
	<joint name="joint_2" type="continuous">
		<origin xyz="-0.0069935 -0.6648493966799938 0.04702981236511938"/>
		<axis xyz="1 0 0"/>
		<child link="link_2"/>
		<parent link="link_0"/>
	</joint>
	<link name="link_3">
		<visual name="caster_stem-30">
			<origin xyz="-0.4333105 0 -0.1777125"/>
			<geometry>
				<mesh filename="textured_objs/original-29.obj"/>
			</geometry>
		</visual>
		<collision>
			<origin xyz="-0.4333105 0 -0.1777125"/>
			<geometry>
				<mesh filename="textured_objs/original-29.obj"/>
			</geometry>
		</collision>
	</link>
	<joint name="joint_3" type="continuous">
		<origin xyz="0.4333105 0 0.1777125"/>
		<axis xyz="0 1 0"/>
		<child link="link_3"/>
		<parent link="link_16"/>
	</joint>
	<link name="link_4">
		<visual name="wheel-31">
			<origin xyz="0 0.664918865712339 -0.22481660868780365"/>
			<geometry>
				<mesh filename="textured_objs/original-27.obj"/>
			</geometry>
		</visual>
		<collision>
			<origin xyz="0 0.664918865712339 -0.22481660868780365"/>
			<geometry>
				<mesh filename="textured_objs/original-27.obj"/>
			</geometry>
		</collision>
	</link>
	<joint name="joint_4" type="continuous">
		<origin xyz="-0.4333105 -0.664918865712339 0.04710410868780365"/>
		<axis xyz="1 0 0"/>
		<child link="link_4"/>
		<parent link="link_3"/>
	</joint>
	<link name="link_5">
		<visual name="wheel-32">
			<origin xyz="-0.0021330995253785352 0.6616297186300059 -0.23744734422449318"/>
			<geometry>
				<mesh filename="textured_objs/original-28.obj"/>
			</geometry>
		</visual>
		<collision>
			<origin xyz="-0.0021330995253785352 0.6616297186300059 -0.23744734422449318"/>
			<geometry>
				<mesh filename="textured_objs/original-28.obj"/>
			</geometry>
		</collision>
	</link>
	<joint name="joint_5" type="continuous">
		<origin xyz="-0.43117740047462144 -0.6616297186300059 0.05973484422449318"/>
		<axis xyz="-0.9994908309717804 0.00787443135093165 0.030920416139498006"/>
		<child link="link_5"/>
		<parent link="link_3"/>
	</joint>
	<link name="link_6">
		<visual name="caster_stem-27">
			<origin xyz="-0.26091149999999996 0 0.3010635"/>
			<geometry>
				<mesh filename="textured_objs/original-16.obj"/>
			</geometry>
		</visual>
		<collision>
			<origin xyz="-0.26091149999999996 0 0.3010635"/>
			<geometry>
				<mesh filename="textured_objs/original-16.obj"/>
			</geometry>
		</collision>
	</link>
	<joint name="joint_6" type="continuous">
		<origin xyz="0.26091149999999996 0 -0.3010635"/>
		<axis xyz="0 1 0"/>
		<child link="link_6"/>
		<parent link="link_16"/>
	</joint>
	<link name="link_7">
		<visual name="wheel-28">
			<origin xyz="0 0.6649678548526803 0.27925787467579255"/>
			<geometry>
				<mesh filename="textured_objs/original-15.obj"/>
			</geometry>
		</visual>
		<collision>
			<origin xyz="0 0.6649678548526803 0.27925787467579255"/>
			<geometry>
				<mesh filename="textured_objs/original-15.obj"/>
			</geometry>
		</collision>
	</link>
	<joint name="joint_7" type="continuous">
		<origin xyz="-0.26091149999999996 -0.6649678548526803 0.021805625324207434"/>
		<axis xyz="1 0 0"/>
		<child link="link_7"/>
		<parent link="link_6"/>
	</joint>
	<link name="link_8">
		<visual name="wheel-29">
			<origin xyz="0 0.6649678548526803 0.27925787467579255"/>
			<geometry>
				<mesh filename="textured_objs/original-17.obj"/>
			</geometry>
		</visual>
		<collision>
			<origin xyz="0 0.6649678548526803 0.27925787467579255"/>
			<geometry>
				<mesh filename="textured_objs/original-17.obj"/>
			</geometry>
		</collision>
	</link>
	<joint name="joint_8" type="continuous">
		<origin xyz="-0.26091149999999996 -0.6649678548526803 0.021805625324207434"/>
		<axis xyz="1 0 0"/>
		<child link="link_8"/>
		<parent link="link_6"/>
	</joint>
	<link name="link_9">
		<visual name="caster_stem-24">
			<origin xyz="0.26760249999999997 0 0.3015725"/>
			<geometry>
				<mesh filename="textured_objs/original-20.obj"/>
			</geometry>
		</visual>
		<collision>
			<origin xyz="0.26760249999999997 0 0.3015725"/>
			<geometry>
				<mesh filename="textured_objs/original-20.obj"/>
			</geometry>
		</collision>
	</link>
	<joint name="joint_9" type="continuous">
		<origin xyz="-0.26760249999999997 0 -0.3015725"/>
		<axis xyz="0 1 0"/>
		<child link="link_9"/>
		<parent link="link_16"/>
	</joint>
	<link name="link_10">
		<visual name="wheel-25">
			<origin xyz="0 0.6649678548526803 0.27925787467579255"/>
			<geometry>
				<mesh filename="textured_objs/original-19.obj"/>
			</geometry>
		</visual>
		<collision>
			<origin xyz="0 0.6649678548526803 0.27925787467579255"/>
			<geometry>
				<mesh filename="textured_objs/original-19.obj"/>
			</geometry>
		</collision>
	</link>
	<joint name="joint_10" type="continuous">
		<origin xyz="0.26760249999999997 -0.6649678548526803 0.02231462532420747"/>
		<axis xyz="1 0 0"/>
		<child link="link_10"/>
		<parent link="link_9"/>
	</joint>
	<link name="link_11">
		<visual name="wheel-26">
			<origin xyz="0 0.6649678548526803 0.27925787467579255"/>
			<geometry>
				<mesh filename="textured_objs/original-18.obj"/>
			</geometry>
		</visual>
		<collision>
			<origin xyz="0 0.6649678548526803 0.27925787467579255"/>
			<geometry>
				<mesh filename="textured_objs/original-18.obj"/>
			</geometry>
		</collision>
	</link>
	<joint name="joint_11" type="continuous">
		<origin xyz="0.26760249999999997 -0.6649678548526803 0.02231462532420747"/>
		<axis xyz="1 0 0"/>
		<child link="link_11"/>
		<parent link="link_9"/>
	</joint>
	<link name="link_12">
		<visual name="caster_stem-21">
			<origin xyz="0.430953 0 -0.201757"/>
			<geometry>
				<mesh filename="textured_objs/original-23.obj"/>
			</geometry>
		</visual>
		<collision>
			<origin xyz="0.430953 0 -0.201757"/>
			<geometry>
				<mesh filename="textured_objs/original-23.obj"/>
			</geometry>
		</collision>
	</link>
	<joint name="joint_12" type="continuous">
		<origin xyz="-0.430953 0 0.201757"/>
		<axis xyz="0 1 0"/>
		<child link="link_12"/>
		<parent link="link_16"/>
	</joint>
	<link name="link_13">
		<visual name="wheel-22">
			<origin xyz="0 0.6649679093392156 -0.2236058183643991"/>
			<geometry>
				<mesh filename="textured_objs/original-22.obj"/>
			</geometry>
		</visual>
		<collision>
			<origin xyz="0 0.6649679093392156 -0.2236058183643991"/>
			<geometry>
				<mesh filename="textured_objs/original-22.obj"/>
			</geometry>
		</collision>
	</link>
	<joint name="joint_13" type="continuous">
		<origin xyz="0.430953 -0.6649679093392156 0.021848818364399114"/>
		<axis xyz="1 0 0"/>
		<child link="link_13"/>
		<parent link="link_12"/>
	</joint>
	<link name="link_14">
		<visual name="wheel-23">
			<origin xyz="0 0.6649679093392156 -0.2236058183643991"/>
			<geometry>
				<mesh filename="textured_objs/original-21.obj"/>
			</geometry>
		</visual>
		<collision>
			<origin xyz="0 0.6649679093392156 -0.2236058183643991"/>
			<geometry>
				<mesh filename="textured_objs/original-21.obj"/>
			</geometry>
		</collision>
	</link>
	<joint name="joint_14" type="continuous">
		<origin xyz="0.430953 -0.6649679093392156 0.021848818364399114"/>
		<axis xyz="1 0 0"/>
		<child link="link_14"/>
		<parent link="link_12"/>
	</joint>
	<link name="link_15">
		<visual name="headrest-50">
			<origin xyz="-0.008045592793736 0 -0.060616659688683586"/>
			<geometry>
				<mesh filename="textured_objs/original-33.obj"/>
			</geometry>
		</visual>
		<visual name="headrest-50">
			<origin xyz="-0.008045592793736 0 -0.060616659688683586"/>
			<geometry>
				<mesh filename="textured_objs/original-32.obj"/>
			</geometry>
		</visual>
		<visual name="head_connector-51">
			<origin xyz="-0.008045592793736 0 -0.060616659688683586"/>
			<geometry>
				<mesh filename="textured_objs/original-34.obj"/>
			</geometry>
		</visual>
		<visual name="back_hard_surface-47">
			<origin xyz="-0.008045592793736 0 -0.060616659688683586"/>
			<geometry>
				<mesh filename="textured_objs/new-41.obj"/>
			</geometry>
		</visual>
		<visual name="back_hard_surface-47">
			<origin xyz="-0.008045592793736 0 -0.060616659688683586"/>
			<geometry>
				<mesh filename="textured_objs/original-9.obj"/>
			</geometry>
		</visual>
		<visual name="back_hard_surface-47">
			<origin xyz="-0.008045592793736 0 -0.060616659688683586"/>
			<geometry>
				<mesh filename="textured_objs/original-35.obj"/>
			</geometry>
		</visual>
		<visual name="back_hard_surface-47">
			<origin xyz="-0.008045592793736 0 -0.060616659688683586"/>
			<geometry>
				<mesh filename="textured_objs/original-40.obj"/>
			</geometry>
		</visual>
		<visual name="back_hard_surface-47">
			<origin xyz="-0.008045592793736 0 -0.060616659688683586"/>
			<geometry>
				<mesh filename="textured_objs/original-38.obj"/>
			</geometry>
		</visual>
		<visual name="back_hard_surface-47">
			<origin xyz="-0.008045592793736 0 -0.060616659688683586"/>
			<geometry>
				<mesh filename="textured_objs/original-39.obj"/>
			</geometry>
		</visual>
		<visual name="back_hard_surface-47">
			<origin xyz="-0.008045592793736 0 -0.060616659688683586"/>
			<geometry>
				<mesh filename="textured_objs/original-41.obj"/>
			</geometry>
		</visual>
		<visual name="back_hard_surface-47">
			<origin xyz="-0.008045592793736 0 -0.060616659688683586"/>
			<geometry>
				<mesh filename="textured_objs/original-44.obj"/>
			</geometry>
		</visual>
		<visual name="back_hard_surface-47">
			<origin xyz="-0.008045592793736 0 -0.060616659688683586"/>
			<geometry>
				<mesh filename="textured_objs/original-36.obj"/>
			</geometry>
		</visual>
		<visual name="back_support-46">
			<origin xyz="-0.008045592793736 0 -0.060616659688683586"/>
			<geometry>
				<mesh filename="textured_objs/new-45.obj"/>
			</geometry>
		</visual>
		<visual name="back_support-46">
			<origin xyz="-0.008045592793736 0 -0.060616659688683586"/>
			<geometry>
				<mesh filename="textured_objs/original-42.obj"/>
			</geometry>
		</visual>
		<visual name="back_support-46">
			<origin xyz="-0.008045592793736 0 -0.060616659688683586"/>
			<geometry>
				<mesh filename="textured_objs/original-31.obj"/>
			</geometry>
		</visual>
		<visual name="back_support-46">
			<origin xyz="-0.008045592793736 0 -0.060616659688683586"/>
			<geometry>
				<mesh filename="textured_objs/original-45.obj"/>
			</geometry>
		</visual>
		<visual name="back_support-46">
			<origin xyz="-0.008045592793736 0 -0.060616659688683586"/>
			<geometry>
				<mesh filename="textured_objs/original-43.obj"/>
			</geometry>
		</visual>
		<visual name="back_support-46">
			<origin xyz="-0.008045592793736 0 -0.060616659688683586"/>
			<geometry>
				<mesh filename="textured_objs/original-37.obj"/>
			</geometry>
		</visual>
		<visual name="back_connector-48">
			<origin xyz="-0.008045592793736 0 -0.060616659688683586"/>
			<geometry>
				<mesh filename="textured_objs/new-51.obj"/>
			</geometry>
		</visual>
		<visual name="back_connector-49">
			<origin xyz="-0.008045592793736 0 -0.060616659688683586"/>
			<geometry>
				<mesh filename="textured_objs/new-50.obj"/>
			</geometry>
		</visual>
		<visual name="armrest_hard_surface-42">
			<origin xyz="-0.008045592793736 0 -0.060616659688683586"/>
			<geometry>
				<mesh filename="textured_objs/original-8.obj"/>
			</geometry>
		</visual>
		<visual name="arm_vertical_bar-43">
			<origin xyz="-0.008045592793736 0 -0.060616659688683586"/>
			<geometry>
				<mesh filename="textured_objs/new-53.obj"/>
			</geometry>
		</visual>
		<visual name="arm_connector-44">
			<origin xyz="-0.008045592793736 0 -0.060616659688683586"/>
			<geometry>
				<mesh filename="textured_objs/new-39.obj"/>
			</geometry>
		</visual>
		<visual name="arm_connector-44">
			<origin xyz="-0.008045592793736 0 -0.060616659688683586"/>
			<geometry>
				<mesh filename="textured_objs/new-42.obj"/>
			</geometry>
		</visual>
		<visual name="armrest_hard_surface-39">
			<origin xyz="-0.008045592793736 0 -0.060616659688683586"/>
			<geometry>
				<mesh filename="textured_objs/original-7.obj"/>
			</geometry>
		</visual>
		<visual name="arm_vertical_bar-40">
			<origin xyz="-0.008045592793736 0 -0.060616659688683586"/>
			<geometry>
				<mesh filename="textured_objs/new-38.obj"/>
			</geometry>
		</visual>
		<visual name="arm_connector-41">
			<origin xyz="-0.008045592793736 0 -0.060616659688683586"/>
			<geometry>
				<mesh filename="textured_objs/new-37.obj"/>
			</geometry>
		</visual>
		<visual name="seat_hard_surface-38">
			<origin xyz="-0.008045592793736 0 -0.060616659688683586"/>
			<geometry>
				<mesh filename="textured_objs/original-46.obj"/>
			</geometry>
		</visual>
		<visual name="seat_hard_surface-38">
			<origin xyz="-0.008045592793736 0 -0.060616659688683586"/>
			<geometry>
				<mesh filename="textured_objs/original-30.obj"/>
			</geometry>
		</visual>
		<visual name="seat_support-37">
			<origin xyz="-0.008045592793736 0 -0.060616659688683586"/>
			<geometry>
				<mesh filename="textured_objs/original-14.obj"/>
			</geometry>
		</visual>
		<visual name="seat_connector-10">
			<origin xyz="-0.008045592793736 0 -0.060616659688683586"/>
			<geometry>
				<mesh filename="textured_objs/new-27.obj"/>
			</geometry>
		</visual>
		<collision>
			<origin xyz="-0.008045592793736 0 -0.060616659688683586"/>
			<geometry>
				<mesh filename="textured_objs/original-33.obj"/>
			</geometry>
		</collision>
		<collision>
			<origin xyz="-0.008045592793736 0 -0.060616659688683586"/>
			<geometry>
				<mesh filename="textured_objs/original-32.obj"/>
			</geometry>
		</collision>
		<collision>
			<origin xyz="-0.008045592793736 0 -0.060616659688683586"/>
			<geometry>
				<mesh filename="textured_objs/original-34.obj"/>
			</geometry>
		</collision>
		<collision>
			<origin xyz="-0.008045592793736 0 -0.060616659688683586"/>
			<geometry>
				<mesh filename="textured_objs/new-41.obj"/>
			</geometry>
		</collision>
		<collision>
			<origin xyz="-0.008045592793736 0 -0.060616659688683586"/>
			<geometry>
				<mesh filename="textured_objs/original-9.obj"/>
			</geometry>
		</collision>
		<collision>
			<origin xyz="-0.008045592793736 0 -0.060616659688683586"/>
			<geometry>
				<mesh filename="textured_objs/original-35.obj"/>
			</geometry>
		</collision>
		<collision>
			<origin xyz="-0.008045592793736 0 -0.060616659688683586"/>
			<geometry>
				<mesh filename="textured_objs/original-40.obj"/>
			</geometry>
		</collision>
		<collision>
			<origin xyz="-0.008045592793736 0 -0.060616659688683586"/>
			<geometry>
				<mesh filename="textured_objs/original-38.obj"/>
			</geometry>
		</collision>
		<collision>
			<origin xyz="-0.008045592793736 0 -0.060616659688683586"/>
			<geometry>
				<mesh filename="textured_objs/original-39.obj"/>
			</geometry>
		</collision>
		<collision>
			<origin xyz="-0.008045592793736 0 -0.060616659688683586"/>
			<geometry>
				<mesh filename="textured_objs/original-41.obj"/>
			</geometry>
		</collision>
		<collision>
			<origin xyz="-0.008045592793736 0 -0.060616659688683586"/>
			<geometry>
				<mesh filename="textured_objs/original-44.obj"/>
			</geometry>
		</collision>
		<collision>
			<origin xyz="-0.008045592793736 0 -0.060616659688683586"/>
			<geometry>
				<mesh filename="textured_objs/original-36.obj"/>
			</geometry>
		</collision>
		<collision>
			<origin xyz="-0.008045592793736 0 -0.060616659688683586"/>
			<geometry>
				<mesh filename="textured_objs/new-45.obj"/>
			</geometry>
		</collision>
		<collision>
			<origin xyz="-0.008045592793736 0 -0.060616659688683586"/>
			<geometry>
				<mesh filename="textured_objs/original-42.obj"/>
			</geometry>
		</collision>
		<collision>
			<origin xyz="-0.008045592793736 0 -0.060616659688683586"/>
			<geometry>
				<mesh filename="textured_objs/original-31.obj"/>
			</geometry>
		</collision>
		<collision>
			<origin xyz="-0.008045592793736 0 -0.060616659688683586"/>
			<geometry>
				<mesh filename="textured_objs/original-45.obj"/>
			</geometry>
		</collision>
		<collision>
			<origin xyz="-0.008045592793736 0 -0.060616659688683586"/>
			<geometry>
				<mesh filename="textured_objs/original-43.obj"/>
			</geometry>
		</collision>
		<collision>
			<origin xyz="-0.008045592793736 0 -0.060616659688683586"/>
			<geometry>
				<mesh filename="textured_objs/original-37.obj"/>
			</geometry>
		</collision>
		<collision>
			<origin xyz="-0.008045592793736 0 -0.060616659688683586"/>
			<geometry>
				<mesh filename="textured_objs/new-51.obj"/>
			</geometry>
		</collision>
		<collision>
			<origin xyz="-0.008045592793736 0 -0.060616659688683586"/>
			<geometry>
				<mesh filename="textured_objs/new-50.obj"/>
			</geometry>
		</collision>
		<collision>
			<origin xyz="-0.008045592793736 0 -0.060616659688683586"/>
			<geometry>
				<mesh filename="textured_objs/original-8.obj"/>
			</geometry>
		</collision>
		<collision>
			<origin xyz="-0.008045592793736 0 -0.060616659688683586"/>
			<geometry>
				<mesh filename="textured_objs/new-53.obj"/>
			</geometry>
		</collision>
		<collision>
			<origin xyz="-0.008045592793736 0 -0.060616659688683586"/>
			<geometry>
				<mesh filename="textured_objs/new-39.obj"/>
			</geometry>
		</collision>
		<collision>
			<origin xyz="-0.008045592793736 0 -0.060616659688683586"/>
			<geometry>
				<mesh filename="textured_objs/new-42.obj"/>
			</geometry>
		</collision>
		<collision>
			<origin xyz="-0.008045592793736 0 -0.060616659688683586"/>
			<geometry>
				<mesh filename="textured_objs/original-7.obj"/>
			</geometry>
		</collision>
		<collision>
			<origin xyz="-0.008045592793736 0 -0.060616659688683586"/>
			<geometry>
				<mesh filename="textured_objs/new-38.obj"/>
			</geometry>
		</collision>
		<collision>
			<origin xyz="-0.008045592793736 0 -0.060616659688683586"/>
			<geometry>
				<mesh filename="textured_objs/new-37.obj"/>
			</geometry>
		</collision>
		<collision>
			<origin xyz="-0.008045592793736 0 -0.060616659688683586"/>
			<geometry>
				<mesh filename="textured_objs/original-46.obj"/>
			</geometry>
		</collision>
		<collision>
			<origin xyz="-0.008045592793736 0 -0.060616659688683586"/>
			<geometry>
				<mesh filename="textured_objs/original-30.obj"/>
			</geometry>
		</collision>
		<collision>
			<origin xyz="-0.008045592793736 0 -0.060616659688683586"/>
			<geometry>
				<mesh filename="textured_objs/original-14.obj"/>
			</geometry>
		</collision>
		<collision>
			<origin xyz="-0.008045592793736 0 -0.060616659688683586"/>
			<geometry>
				<mesh filename="textured_objs/new-27.obj"/>
			</geometry>
		</collision>
	</link>
	<joint name="joint_15" type="continuous">
		<origin xyz="0.0 0 0.0"/>
		<axis xyz="0 1 0"/>
		<child link="link_15"/>
		<parent link="link_15_helper"/>
	</joint>
	<link name="link_16">
		<visual name="central_support-8">
			<origin xyz="0 0 0"/>
			<geometry>
				<mesh filename="textured_objs/new-28.obj"/>
			</geometry>
		</visual>
		<visual name="central_support-8">
			<origin xyz="0 0 0"/>
			<geometry>
				<mesh filename="textured_objs/new-34.obj"/>
			</geometry>
		</visual>
		<visual name="central_support-8">
			<origin xyz="0 0 0"/>
			<geometry>
				<mesh filename="textured_objs/original-11.obj"/>
			</geometry>
		</visual>
		<visual name="central_support-8">
			<origin xyz="0 0 0"/>
			<geometry>
				<mesh filename="textured_objs/original-12.obj"/>
			</geometry>
		</visual>
		<visual name="leg-11">
			<origin xyz="0 0 0"/>
			<geometry>
				<mesh filename="textured_objs/new-29.obj"/>
			</geometry>
		</visual>
		<visual name="leg-12">
			<origin xyz="0 0 0"/>
			<geometry>
				<mesh filename="textured_objs/new-33.obj"/>
			</geometry>
		</visual>
		<visual name="leg-13">
			<origin xyz="0 0 0"/>
			<geometry>
				<mesh filename="textured_objs/new-32.obj"/>
			</geometry>
		</visual>
		<visual name="leg-14">
			<origin xyz="0 0 0"/>
			<geometry>
				<mesh filename="textured_objs/new-31.obj"/>
			</geometry>
		</visual>
		<visual name="leg-15">
			<origin xyz="0 0 0"/>
			<geometry>
				<mesh filename="textured_objs/new-30.obj"/>
			</geometry>
		</visual>
		<collision>
			<origin xyz="0 0 0"/>
			<geometry>
				<mesh filename="textured_objs/new-28.obj"/>
			</geometry>
		</collision>
		<collision>
			<origin xyz="0 0 0"/>
			<geometry>
				<mesh filename="textured_objs/new-34.obj"/>
			</geometry>
		</collision>
		<collision>
			<origin xyz="0 0 0"/>
			<geometry>
				<mesh filename="textured_objs/original-11.obj"/>
			</geometry>
		</collision>
		<collision>
			<origin xyz="0 0 0"/>
			<geometry>
				<mesh filename="textured_objs/original-12.obj"/>
			</geometry>
		</collision>
		<collision>
			<origin xyz="0 0 0"/>
			<geometry>
				<mesh filename="textured_objs/new-29.obj"/>
			</geometry>
		</collision>
		<collision>
			<origin xyz="0 0 0"/>
			<geometry>
				<mesh filename="textured_objs/new-33.obj"/>
			</geometry>
		</collision>
		<collision>
			<origin xyz="0 0 0"/>
			<geometry>
				<mesh filename="textured_objs/new-32.obj"/>
			</geometry>
		</collision>
		<collision>
			<origin xyz="0 0 0"/>
			<geometry>
				<mesh filename="textured_objs/new-31.obj"/>
			</geometry>
		</collision>
		<collision>
			<origin xyz="0 0 0"/>
			<geometry>
				<mesh filename="textured_objs/new-30.obj"/>
			</geometry>
		</collision>
	</link>
	<joint name="joint_16" type="fixed">
		<origin rpy="1.570796326794897 0 -1.570796326794897" xyz="0 0 0"/>
		<child link="link_16"/>
		<parent link="base"/>
	</joint>
	<link name="link_15_helper"/>
	<joint name="joint_17" type="prismatic">
		<origin xyz="0.008045592793736 0 0.060616659688683586"/>
		<axis xyz="0 -1 0"/>
		<child link="link_15_helper"/>
		<parent link="link_16"/>
		<limit lower="0" upper="0.1"/>
	</joint>
</robot>
