<?xml version="1.0" encoding="utf-8"?>
<robot name="partnet_99120ec1daa4ae1bad484915511ccff6">
 <link name="base"/>
 <link name="link_0">
  <visual name="lever-76">
   <origin xyz="-0.12042415942996744 0.17889561294307413 0"/>
   <geometry>
    <mesh filename="textured_objs/original-30.obj"/>
   </geometry>
  </visual>
  <visual name="lever-76">
   <origin xyz="-0.12042415942996744 0.17889561294307413 0"/>
   <geometry>
    <mesh filename="textured_objs/original-32.obj"/>
   </geometry>
  </visual>
  <visual name="lever-76">
   <origin xyz="-0.12042415942996744 0.17889561294307413 0"/>
   <geometry>
    <mesh filename="textured_objs/original-31.obj"/>
   </geometry>
  </visual>
  <collision>
   <geometry>
    <mesh filename="cvx_objs/link_0.obj"/>
   </geometry>
  </collision>
 </link>
 <joint name="joint_0" type="revolute">
  <origin xyz="0.13219904197639668 -0.17889561294307413 -0.022481716908374236"/>
  <axis xyz="0 0 -1"/>
  <child link="link_0"/>
  <parent link="link_16"/>
  <limit lower="-0.0" upper="0.3204424506661591"/>
 </joint>
 <link name="link_1">
  <visual name="caster_stem-102">
   <origin xyz="0.5227210218181609 0 0.14397391162969364"/>
   <geometry>
    <mesh filename="textured_objs/original-46.obj"/>
   </geometry>
  </visual>
  <collision>
   <geometry>
    <mesh filename="cvx_objs/link_1.obj"/>
   </geometry>
  </collision>
 </link>
 <joint name="joint_1" type="continuous">
  <origin xyz="-0.5227210218181609 0 -0.14397391162969364"/>
  <axis xyz="0 1 0"/>
  <child link="link_1"/>
  <parent link="link_17"/>
 </joint>
 <link name="link_2">
  <visual name="wheel-103">
   <origin xyz="-0.0065671911528872055 0.7060431671475953 0.10813501688948095"/>
   <geometry>
    <mesh filename="textured_objs/original-44.obj"/>
   </geometry>
  </visual>
  <collision>
   <geometry>
    <mesh filename="cvx_objs/link_2.obj"/>
   </geometry>
  </collision>
 </link>
 <joint name="joint_2" type="continuous">
  <origin xyz="0.5292882129710481 -0.7060431671475953 0.03583889474021269"/>
  <axis xyz="0.9999566980936941 0.009305959844037686 -3.238730896646673e-05"/>
  <child link="link_2"/>
  <parent link="link_1"/>
 </joint>
 <link name="link_3">
  <visual name="wheel-104">
   <origin xyz="0 0.7107210056808267 0.10811899999999999"/>
   <geometry>
    <mesh filename="textured_objs/original-45.obj"/>
   </geometry>
  </visual>
  <collision>
   <geometry>
    <mesh filename="cvx_objs/link_3.obj"/>
   </geometry>
  </collision>
 </link>
 <joint name="joint_3" type="continuous">
  <origin xyz="0.5227210218181609 -0.7107210056808267 0.03585491162969365"/>
  <axis xyz="1 0 0"/>
  <child link="link_3"/>
  <parent link="link_1"/>
 </joint>
 <link name="link_4">
  <visual name="caster_stem-99">
   <origin xyz="0.32877011449438337 0 -0.4601039954670883"/>
   <geometry>
    <mesh filename="textured_objs/original-38.obj"/>
   </geometry>
  </visual>
  <collision>
   <geometry>
    <mesh filename="cvx_objs/link_4.obj"/>
   </geometry>
  </collision>
 </link>
 <joint name="joint_4" type="continuous">
  <origin xyz="-0.32877011449438337 0 0.4601039954670883"/>
  <axis xyz="0 1 0"/>
  <child link="link_4"/>
  <parent link="link_17"/>
 </joint>
 <link name="link_5">
  <visual name="wheel-100">
   <origin xyz="0 0.7107210056808267 -0.495245"/>
   <geometry>
    <mesh filename="textured_objs/original-36.obj"/>
   </geometry>
  </visual>
  <collision>
   <geometry>
    <mesh filename="cvx_objs/link_5.obj"/>
   </geometry>
  </collision>
 </link>
 <joint name="joint_5" type="continuous">
  <origin xyz="0.32877011449438337 -0.7107210056808267 0.03514100453291169"/>
  <axis xyz="-1 0 0"/>
  <child link="link_5"/>
  <parent link="link_4"/>
 </joint>
 <link name="link_6">
  <visual name="wheel-101">
   <origin xyz="0 0.7107210056808267 -0.495245"/>
   <geometry>
    <mesh filename="textured_objs/original-37.obj"/>
   </geometry>
  </visual>
  <collision>
   <geometry>
    <mesh filename="cvx_objs/link_6.obj"/>
   </geometry>
  </collision>
 </link>
 <joint name="joint_6" type="continuous">
  <origin xyz="0.32877011449438337 -0.7107210056808267 0.03514100453291169"/>
  <axis xyz="-1 0 0"/>
  <child link="link_6"/>
  <parent link="link_4"/>
 </joint>
 <link name="link_7">
  <visual name="caster_stem-96">
   <origin xyz="-0.30586192690503605 0 -0.4606418216372392"/>
   <geometry>
    <mesh filename="textured_objs/original-42.obj"/>
   </geometry>
  </visual>
  <collision>
   <geometry>
    <mesh filename="cvx_objs/link_7.obj"/>
   </geometry>
  </collision>
 </link>
 <joint name="joint_7" type="continuous">
  <origin xyz="0.30586192690503605 0 0.4606418216372392"/>
  <axis xyz="0 1 0"/>
  <child link="link_7"/>
  <parent link="link_17"/>
 </joint>
 <link name="link_8">
  <visual name="wheel-97">
   <origin xyz="0 0.7107210056808267 -0.495245"/>
   <geometry>
    <mesh filename="textured_objs/original-40.obj"/>
   </geometry>
  </visual>
  <collision>
   <geometry>
    <mesh filename="cvx_objs/link_8.obj"/>
   </geometry>
  </collision>
 </link>
 <joint name="joint_8" type="continuous">
  <origin xyz="-0.30586192690503605 -0.7107210056808267 0.03460317836276078"/>
  <axis xyz="-1 0 0"/>
  <child link="link_8"/>
  <parent link="link_7"/>
 </joint>
 <link name="link_9">
  <visual name="wheel-98">
   <origin xyz="0 0.7107210056808267 -0.495245"/>
   <geometry>
    <mesh filename="textured_objs/original-41.obj"/>
   </geometry>
  </visual>
  <collision>
   <geometry>
    <mesh filename="cvx_objs/link_9.obj"/>
   </geometry>
  </collision>
 </link>
 <joint name="joint_9" type="continuous">
  <origin xyz="-0.30586192690503605 -0.7107210056808267 0.03460317836276078"/>
  <axis xyz="-1 0 0"/>
  <child link="link_9"/>
  <parent link="link_7"/>
 </joint>
 <link name="link_10">
  <visual name="caster_stem-93">
   <origin xyz="0.010786704643964765 0 0.5170993392990177"/>
   <geometry>
    <mesh filename="textured_objs/original-54.obj"/>
   </geometry>
  </visual>
  <collision>
   <geometry>
    <mesh filename="cvx_objs/link_10.obj"/>
   </geometry>
  </collision>
 </link>
 <joint name="joint_10" type="continuous">
  <origin xyz="-0.010786704643964765 0 -0.5170993392990177"/>
  <axis xyz="0 1 0"/>
  <child link="link_10"/>
  <parent link="link_17"/>
 </joint>
 <link name="link_11">
  <visual name="wheel-94">
   <origin xyz="0 0.7107210056808267 0.481251"/>
   <geometry>
    <mesh filename="textured_objs/original-53.obj"/>
   </geometry>
  </visual>
  <collision>
   <geometry>
    <mesh filename="cvx_objs/link_11.obj"/>
   </geometry>
  </collision>
 </link>
 <joint name="joint_11" type="continuous">
  <origin xyz="0.010786704643964765 -0.7107210056808267 0.03584833929901776"/>
  <axis xyz="1 0 0"/>
  <child link="link_11"/>
  <parent link="link_10"/>
 </joint>
 <link name="link_12">
  <visual name="wheel-95">
   <origin xyz="0 0.7107210056808267 0.481251"/>
   <geometry>
    <mesh filename="textured_objs/original-52.obj"/>
   </geometry>
  </visual>
  <collision>
   <geometry>
    <mesh filename="cvx_objs/link_12.obj"/>
   </geometry>
  </collision>
 </link>
 <joint name="joint_12" type="continuous">
  <origin xyz="0.010786704643964765 -0.7107210056808267 0.03584833929901776"/>
  <axis xyz="1 0 0"/>
  <child link="link_12"/>
  <parent link="link_10"/>
 </joint>
 <link name="link_13">
  <visual name="caster_stem-87">
   <origin xyz="-0.502498314630747 0 0.14401355345049882"/>
   <geometry>
    <mesh filename="textured_objs/original-50.obj"/>
   </geometry>
  </visual>
  <collision>
   <geometry>
    <mesh filename="cvx_objs/link_13.obj"/>
   </geometry>
  </collision>
 </link>
 <joint name="joint_13" type="continuous">
  <origin xyz="0.502498314630747 0 -0.14401355345049882"/>
  <axis xyz="0 1 0"/>
  <child link="link_13"/>
  <parent link="link_17"/>
 </joint>
 <link name="link_14">
  <visual name="wheel-88">
   <origin xyz="0 0.7107210056808267 0.10811899999999999"/>
   <geometry>
    <mesh filename="textured_objs/original-48.obj"/>
   </geometry>
  </visual>
  <collision>
   <geometry>
    <mesh filename="cvx_objs/link_14.obj"/>
   </geometry>
  </collision>
 </link>
 <joint name="joint_14" type="continuous">
  <origin xyz="-0.502498314630747 -0.7107210056808267 0.03589455345049883"/>
  <axis xyz="-1 0 0"/>
  <child link="link_14"/>
  <parent link="link_13"/>
 </joint>
 <link name="link_15">
  <visual name="wheel-89">
   <origin xyz="0 0.7107210056808267 0.10811899999999999"/>
   <geometry>
    <mesh filename="textured_objs/original-49.obj"/>
   </geometry>
  </visual>
  <collision>
   <geometry>
    <mesh filename="cvx_objs/link_15.obj"/>
   </geometry>
  </collision>
 </link>
 <joint name="joint_15" type="continuous">
  <origin xyz="-0.502498314630747 -0.7107210056808267 0.03589455345049883"/>
  <axis xyz="-1 0 0"/>
  <child link="link_15"/>
  <parent link="link_13"/>
 </joint>
 <link name="link_16">
  <visual name="back_holistic_frame-67">
   <origin xyz="0.011774882546429223 0 -0.022481716908374236"/>
   <geometry>
    <mesh filename="textured_objs/new-10.obj"/>
   </geometry>
  </visual>
  <visual name="back_soft_surface-70">
   <origin xyz="0.011774882546429223 0 -0.022481716908374236"/>
   <geometry>
    <mesh filename="textured_objs/original-3.obj"/>
   </geometry>
  </visual>
  <visual name="back_soft_surface-70">
   <origin xyz="0.011774882546429223 0 -0.022481716908374236"/>
   <geometry>
    <mesh filename="textured_objs/original-2.obj"/>
   </geometry>
  </visual>
  <visual name="back_connector-69">
   <origin xyz="0.011774882546429223 0 -0.022481716908374236"/>
   <geometry>
    <mesh filename="textured_objs/new-9.obj"/>
   </geometry>
  </visual>
  <visual name="back_connector-69">
   <origin xyz="0.011774882546429223 0 -0.022481716908374236"/>
   <geometry>
    <mesh filename="textured_objs/original-27.obj"/>
   </geometry>
  </visual>
  <visual name="back_support-72">
   <origin xyz="0.011774882546429223 0 -0.022481716908374236"/>
   <geometry>
    <mesh filename="textured_objs/original-5.obj"/>
   </geometry>
  </visual>
  <visual name="armrest_soft_surface-58">
   <origin xyz="0.011774882546429223 0 -0.022481716908374236"/>
   <geometry>
    <mesh filename="textured_objs/original-18.obj"/>
   </geometry>
  </visual>
  <visual name="arm_vertical_bar-59">
   <origin xyz="0.011774882546429223 0 -0.022481716908374236"/>
   <geometry>
    <mesh filename="textured_objs/original-13.obj"/>
   </geometry>
  </visual>
  <visual name="arm_vertical_bar-59">
   <origin xyz="0.011774882546429223 0 -0.022481716908374236"/>
   <geometry>
    <mesh filename="textured_objs/original-16.obj"/>
   </geometry>
  </visual>
  <visual name="arm_horizontal_bar-60">
   <origin xyz="0.011774882546429223 0 -0.022481716908374236"/>
   <geometry>
    <mesh filename="textured_objs/original-15.obj"/>
   </geometry>
  </visual>
  <visual name="arm_connector-61">
   <origin xyz="0.011774882546429223 0 -0.022481716908374236"/>
   <geometry>
    <mesh filename="textured_objs/original-14.obj"/>
   </geometry>
  </visual>
  <visual name="armrest_soft_surface-50">
   <origin xyz="0.011774882546429223 0 -0.022481716908374236"/>
   <geometry>
    <mesh filename="textured_objs/original-17.obj"/>
   </geometry>
  </visual>
  <visual name="arm_vertical_bar-51">
   <origin xyz="0.011774882546429223 0 -0.022481716908374236"/>
   <geometry>
    <mesh filename="textured_objs/original-8.obj"/>
   </geometry>
  </visual>
  <visual name="arm_vertical_bar-51">
   <origin xyz="0.011774882546429223 0 -0.022481716908374236"/>
   <geometry>
    <mesh filename="textured_objs/original-11.obj"/>
   </geometry>
  </visual>
  <visual name="arm_horizontal_bar-52">
   <origin xyz="0.011774882546429223 0 -0.022481716908374236"/>
   <geometry>
    <mesh filename="textured_objs/original-10.obj"/>
   </geometry>
  </visual>
  <visual name="arm_connector-53">
   <origin xyz="0.011774882546429223 0 -0.022481716908374236"/>
   <geometry>
    <mesh filename="textured_objs/original-9.obj"/>
   </geometry>
  </visual>
  <visual name="seat_soft_surface-49">
   <origin xyz="0.011774882546429223 0 -0.022481716908374236"/>
   <geometry>
    <mesh filename="textured_objs/original-1.obj"/>
   </geometry>
  </visual>
  <visual name="seat_support-47">
   <origin xyz="0.011774882546429223 0 -0.022481716908374236"/>
   <geometry>
    <mesh filename="textured_objs/original-22.obj"/>
   </geometry>
  </visual>
  <visual name="seat_support-47">
   <origin xyz="0.011774882546429223 0 -0.022481716908374236"/>
   <geometry>
    <mesh filename="textured_objs/original-23.obj"/>
   </geometry>
  </visual>
  <visual name="seat_support-47">
   <origin xyz="0.011774882546429223 0 -0.022481716908374236"/>
   <geometry>
    <mesh filename="textured_objs/original-24.obj"/>
   </geometry>
  </visual>
  <visual name="seat_support-47">
   <origin xyz="0.011774882546429223 0 -0.022481716908374236"/>
   <geometry>
    <mesh filename="textured_objs/original-29.obj"/>
   </geometry>
  </visual>
  <visual name="seat_support-47">
   <origin xyz="0.011774882546429223 0 -0.022481716908374236"/>
   <geometry>
    <mesh filename="textured_objs/original-33.obj"/>
   </geometry>
  </visual>
  <visual name="seat_support-47">
   <origin xyz="0.011774882546429223 0 -0.022481716908374236"/>
   <geometry>
    <mesh filename="textured_objs/original-34.obj"/>
   </geometry>
  </visual>
  <visual name="seat_support-47">
   <origin xyz="0.011774882546429223 0 -0.022481716908374236"/>
   <geometry>
    <mesh filename="textured_objs/original-26.obj"/>
   </geometry>
  </visual>
  <visual name="seat_support-47">
   <origin xyz="0.011774882546429223 0 -0.022481716908374236"/>
   <geometry>
    <mesh filename="textured_objs/original-25.obj"/>
   </geometry>
  </visual>
  <visual name="seat_support-47">
   <origin xyz="0.011774882546429223 0 -0.022481716908374236"/>
   <geometry>
    <mesh filename="textured_objs/original-28.obj"/>
   </geometry>
  </visual>
  <visual name="central_support-7">
   <origin xyz="0.011774882546429223 0 -0.022481716908374236"/>
   <geometry>
    <mesh filename="textured_objs/new-8.obj"/>
   </geometry>
  </visual>
  <collision>
   <geometry>
    <mesh filename="cvx_objs/link_16.obj"/>
   </geometry>
  </collision>
 </link>
 <joint name="joint_16" type="continuous">
  <origin xyz="0.0 0 0.0"/>
  <axis xyz="0 1 0"/>
  <child link="link_16"/>
  <parent link="link_16_helper"/>
 </joint>
 <link name="link_17">
  <visual name="central_support-8">
   <origin xyz="0 0 0"/>
   <geometry>
    <mesh filename="textured_objs/new-7.obj"/>
   </geometry>
  </visual>
  <visual name="central_support-8">
   <origin xyz="0 0 0"/>
   <geometry>
    <mesh filename="textured_objs/new-5.obj"/>
   </geometry>
  </visual>
  <visual name="central_support-9">
   <origin xyz="0 0 0"/>
   <geometry>
    <mesh filename="textured_objs/new-6.obj"/>
   </geometry>
  </visual>
  <visual name="leg-77">
   <origin xyz="0 0 0"/>
   <geometry>
    <mesh filename="textured_objs/new-0.obj"/>
   </geometry>
  </visual>
  <visual name="leg-78">
   <origin xyz="0 0 0"/>
   <geometry>
    <mesh filename="textured_objs/new-4.obj"/>
   </geometry>
  </visual>
  <visual name="leg-79">
   <origin xyz="0 0 0"/>
   <geometry>
    <mesh filename="textured_objs/new-3.obj"/>
   </geometry>
  </visual>
  <visual name="leg-80">
   <origin xyz="0 0 0"/>
   <geometry>
    <mesh filename="textured_objs/new-2.obj"/>
   </geometry>
  </visual>
  <visual name="leg-81">
   <origin xyz="0 0 0"/>
   <geometry>
    <mesh filename="textured_objs/new-1.obj"/>
   </geometry>
  </visual>
  <collision>
   <geometry>
    <mesh filename="cvx_objs/link_17.obj"/>
   </geometry>
  </collision>
 </link>
 <joint name="joint_17" type="fixed">
  <origin rpy="1.570796326794897 0 -1.570796326794897" xyz="0 0 0"/>
  <child link="link_17"/>
  <parent link="base"/>
 </joint>
 <link name="link_16_helper"/>
 <joint name="joint_18" type="prismatic">
  <origin xyz="-0.011774882546429223 0 0.022481716908374236"/>
  <axis xyz="0 -1 0"/>
  <child link="link_16_helper"/>
  <parent link="link_17"/>
  <limit lower="0" upper="0.06800000000000006"/>
 </joint>
</robot>